Workbook
Name 预言: 灵能大全!$C$65:$I$74
Name 次级灵能: 灵能大全!$C$3:$I$50

Sheet 人物
B2: 玩家 | H2: 角色 | T2: 资金 | U2: 启用月工资 | Y2: 合计 | Z2: =IF(X2="是",K7,0)+W3+X5 -> 0
B3: 出身 | H3: 生日 | O3: 月 | Q3: 日 | U3: 行动经费 | Y3: 已用 | Z3: =武备!Q115 -> 0
B4: 职业 | H4: 等级 | J4: =IF(N4="","","Rank "&COUNTIF(Z$35:Z$50,"<="&Q4)+1) | L4: 经验 | M4: 持有 | P4: 已用 | Q4: =IF(N4="","",I22+R58+R99+H138+H109) | U4: 其他收入 | Y4: 剩余 | Z4: =Z2-Z3 -> 0
B6: 社会阶级 | G6: 月入 | H6: 提升 | I6: 起始资金 | K6: 工资总额 | M6: 预言 | N6: 投掷 | O6: =IFERROR(VLOOKUP(N7,人物数据!$A:$B,2,0),"")
G7: =IFERROR(VLOOKUP(B7,职业数据!$E:$G,2,0),"") | H7: =IFERROR(VLOOKUP(B7,职业数据!$E:$G,3,0),"") | K7: {=IF(B7="","",IF(N4<400,0,SUMPRODUCT((ROW(INDIRECT("1:"&INT(N4/400)))*400<=N4)*(G7+(COUNTIFS(Z$35:Z$50,"<="&ROW(INDIRECT("1:"&INT(N4/400)))*400)*H7))))+I7)}
B9: 状态 | D9: 身高 | H9: 虹膜 | L9: 整体 形象
D10: 年龄 | H10: 发型
B12: 属性情况 | D12: 基础 | E12: 超然 | F12: 备注 | G12: 加成 | H12: 训练 | I12: 花费 | J12: 减值 | K12: 最终 | L12: 加值 | M12: 命 运 点 | N12: 失心 | Q12: 堕落 | T12: 角色头像
B13: 近战 WS | E13: 1 | K13: =D13+G13+H13-J13 -> 0 | L13: =INT(K13/10)*E13 -> 0 | S13: 80
B14: 远程 BS | E14: 1 | K14: =D14+G14+H14-J14 -> 0 | L14: =INT(K14/10)*E14 -> 0 | S14: 80
B15: 力量 S | E15: 1 | K15: =D15+G15+H15-J15 -> 0 | L15: =INT(K15/10)*E15 -> 0 | S15: 80
B16: 坚韧 T | E16: 1 | K16: =D16+G16+H16-J16 -> 0 | L16: =INT(K16/10)*E16 -> 0 | S16: 80
B17: 敏捷 Ag | E17: 1 | K17: =D17+G17+H17-J17 -> 0 | L17: =INT(K17/10)*E17 -> 0 | M17: 剩 余 | S17: 80
B18: 智力 Int | E18: 1 | K18: =D18+G18+H18-J18 -> 0 | L18: =INT(K18/10)*E18 -> 0 | S18: 80
B19: 感知 Per | E19: 1 | K19: =D19+G19+H19-J19 -> 0 | L19: =INT(K19/10)*E19 -> 0 | S19: 80
B20: 意志 WP | E20: 1 | K20: =D20+G20+H20-J20 -> 0 | L20: =INT(K20/10)*E20 -> 0 | S20: 80
B21: 交际 Fel | E21: 1 | K21: =D21+G21+H21-J21 -> 0 | L21: =INT(K21/10)*E21 -> 0 | S21: 80
I22: =SUM(I13:I21) -> 0 | W22: 角色
B23: 承伤和防护情况（简） | T23: 致命伤情况
B24: 承伤 | D24: 基础 | F24: 加成 | H24: 备注 | J24: 减值 | L24: 备注 | N24: 最终承伤 | P24: =E24+G24-K24 -> 0 | Q24: 剩余 | T24: 头部 0-1 | Y24: 躯干 31-70
B25: 装备数值 | D25: 头部 0-1 | F25: 右臂 11-20 | H25: 左臂 21-30 | J25: 躯干 31-70 | L25: 右腿 71-85 | N25: 左腿 86-00 | P25: 血肉苦弱 | R25: 0 | T25: 右手 11-20 | Y25: 左手 21-30
B26: 额外护甲 | P26: 特殊护甲 | R26: 无 | T26: 左腿 86-00 | Y26: 左腿 71-85
B27: 额外坚韧 | P27: 坚韧加值 | R27: =L16 -> 0 | T27: 其他 | Y27: 其他
B29: 移动 | D29: 部分 | F29: 完整 | H29: 冲锋 | J29: 奔跑 | L29: 每分钟 | N29: 每小时 | P29: 每天 | R29: 备注 | T29: 负重上限 | V29: =VLOOKUP(V31,人物数据!C2:F22,2,FALSE()) -> 0.9 | X29: 当前负重 | Z29: =武备!Q4+武备!Q14+SUM(武备!Q25:Q29)+SUM(武备!Q33:Q34)+SUM(武备!Q38:Q49)+SUM(武备!Q53:Q67) -> 0
B30: 徒步 | D30: =L17 -> 0 | F30: =D30*2 -> 0 | H30: =D30*3 -> 0 | J30: =D30*6 -> 0 | L30: =VLOOKUP(L17,人物数据!H2:O12,6,FALSE()) -> 12m | N30: =VLOOKUP(L17,人物数据!H2:O12,7,FALSE()) -> 0.75km | P30: =VLOOKUP(L17,人物数据!H2:O12,8,FALSE()) -> 7km | R30: — | T30: 参考值 | V30: SB+TB | X30: 举起 | Z30: 拖拽
B31: 飞跑 | D31: —— | F31: —— | H31: —— | J31: =J30*2 -> 0 | L31: —— | N31: —— | P31: —— | R31: — | V31: =L15+L16 -> 0 | X31: =VLOOKUP(V31,人物数据!C2:F22,3,FALSE()) -> 2.25 | Z31: =VLOOKUP(V31,人物数据!C2:F22,4,FALSE()) -> 4.5
B33: 先攻 | D33: 基础 | F33: 谨小慎微 | H33: 闪电反射 | J33: 巢都出身 | L33: 其他 | N33: 最终 | T33: 进阶情况
D34: =L17 -> 0 | F34: 否 | H34: 否 | J34: 否 | L34: 暂无 | N34: ="1D10+"&(IF(H34="是",D34*2,D34)+IF(F34="是",2,0)+IF(J34="是",1,0)+IF(ISNUMBER(L34),L34,0)) -> 1D10+0 | T34: Rank | U34: 属性 | V34: 技能 | W34: 天赋 | X34: 经验开销（手动）
T35: 1 | X35: =TEXT(SUM(U$35:W35),"0")&"/" -> 0/ | Z35: 500
A36: =".st"&"格斗"&K13&"近战"&K13&"射击"&K14&"远程"&K14&"力量"&K15&"坚韧"&K16&"敏捷"&K17&"智力"&K18&"感知"&K19&"意志"&K20&"交际"&K21&"生命值"&R24&"生命值上限"&P24&"命运点"&M20&"命运点上限"&M15&"威胁"&I38&"恐吓"&I38&"攀爬"&I39&"运动"&I39&B40&I40&"酗酒"&I41&"狂饮"&I41&B42&I42&B43&I43&B44&I44&B45&I45&B46&I46&B47&I47&B48&I48&"搜查"&I49&"搜索"&I49&B50&I50&B51&I51&B52&I52&B53&I53&B54&I54&B55&I55&B56&I56&B57&I57&A71 -> .st格斗0近战0射击0远程0力量0坚韧0敏捷0智力0感知0意志0交际0生命值生命值上限0命运点命运点上限威胁0恐吓0攀爬0运动0游泳0酗酒0狂饮0躲藏0闪避0潜行0估价0逻辑0赌博0警觉0搜查0搜索0察言观色0交易0欺诈0搜集信息0伪装0吸引0扯淡0指挥0 | B36: 基础技能 | T36: 2 | X36: =TEXT(SUM(U$35:W36),"0")&"/" -> 0/ | Z36: 1000
B37: 名称 | D37: 属性 | E37: 受训 | F37: +10 | G37: +20 | H37: 天赋 | I37: 数值 | J37: 其他加成情况 | R37: 花费 | T37: 3 | X37: =TEXT(SUM(U$35:W37),"0")&"/" -> 0/ | Z37: 2000
B38: 威胁/恐吓 | D38: S | I38: =IF(E38<>"",K15,ROUNDUP(K15/2,0))+IF(F38<>"",10,0)+IF(G38<>"",10,0)+IF(H38<>"",10,0) -> 0 | R38: =E38+F38+G38+H38 -> 0 | T38: 4 | X38: =TEXT(SUM(U$35:W38),"0")&"/" -> 0/ | Z38: 3000
B39: 攀爬/运动 | D39: S | I39: =IF(E39<>"",K15,ROUNDUP(K15/2,0))+IF(F39<>"",10,0)+IF(G39<>"",10,0)+IF(H39<>"",10,0) -> 0 | R39: =E39+F39+G39+H39 -> 0 | T39: 5 | X39: =TEXT(SUM(U$35:W39),"0")&"/" -> 0/ | Z39: 5000
B40: 游泳 | D40: S | I40: =IF(E40<>"",K15,ROUNDUP(K15/2,0))+IF(F40<>"",10,0)+IF(G40<>"",10,0)+IF(H40<>"",10,0) -> 0 | R40: =E40+F40+G40+H40 -> 0 | T40: 6 | X40: =TEXT(SUM(U$35:W40),"0")&"/" -> 0/ | Z40: 7000
B41: 酗酒/狂欢 | D41: T | I41: =IF(E41<>"",K16,ROUNDUP(K16/2,0))+IF(F41<>"",10,0)+IF(G41<>"",10,0)+IF(H41<>"",10,0) -> 0 | R41: =E41+F41+G41+H41 -> 0 | T41: 7 | X41: =TEXT(SUM(U$35:W41),"0")&"/" -> 0/ | Z41: 10000
B42: 躲藏 | D42: AG | I42: =IF(E42<>"",K17,ROUNDUP(K17/2,0))+IF(F42<>"",10,0)+IF(G42<>"",10,0)+IF(H42<>"",10,0) -> 0 | R42: =E42+F42+G42+H42 -> 0 | T42: 8 | X42: =TEXT(SUM(U$35:W42),"0")&"/" -> 0/ | Z42: 13000
B43: 闪避 | D43: AG | I43: =IF(E43<>"",K17,ROUNDUP(K17/2,0))+IF(F43<>"",10,0)+IF(G43<>"",10,0)+IF(H43<>"",10,0) -> 0 | R43: =E43+F43+G43+H43 -> 0 | T43: 9 | X43: =TEXT(SUM(U$35:W43),"0")&"/" -> 0/ | Z43: 17000
B44: 潜行 | D44: AG | I44: =IF(E44<>"",K17,ROUNDUP(K17/2,0))+IF(F44<>"",10,0)+IF(G44<>"",10,0)+IF(H44<>"",10,0) -> 0 | R44: =E44+F44+G44+H44 -> 0 | T44: 10 | X44: =TEXT(SUM(U$35:W44),"0")&"/" -> 0/ | Z44: 21000
B45: 估价 | D45: INT | I45: =IF(E45<>"",K18,ROUNDUP(K18/2,0))+IF(F45<>"",10,0)+IF(G45<>"",10,0)+IF(H45<>"",10,0) -> 0 | R45: =E45+F45+G45+H45 -> 0 | T45: 11 | X45: =TEXT(SUM(U$35:W45),"0")&"/" -> 0/ | Z45: 25000
B46: 逻辑 | D46: INT | I46: =IF(E46<>"",K18,ROUNDUP(K18/2,0))+IF(F46<>"",10,0)+IF(G46<>"",10,0)+IF(H46<>"",10,0) -> 0 | R46: =E46+F46+G46+H46 -> 0 | T46: 12 | X46: =TEXT(SUM(U$35:W46),"0")&"/" -> 0/ | Z46: 30000
...

Sheet 武备
B1: 近 战 武 器
B2: 武器名称/类型
B3: 类型 | D3: 伤害 | J3: 破甲 | K3: 特性 | Q3: 重量 | R3: WS
R4: =人物!K$13 -> 0
B5: 武器升级
B8: 相关天赋
B11: 远 程 武 器
B12: 武器名称/类型
B13: 类型 | D13: 射程 | F13: 射速 | I13: 破甲 | J13: 特性 | Q13: 重量 | R13: BS
R14: =人物!K$14 -> 0
B15: 伤害 | I15: 弹药 | O15: 装填
B16: 武器升级
B19: 相关天赋
B23: 弹 药 和 榴 弹 等
B24: 名称 | F24: 类型 | H24: 射程 | I24: 射速 | J24: 伤害 | L24: 破甲 | M24: 弹夹 | N24: 装填 | O24: 特性 | Q24: 重量 | R24: 花费
Q30: =SUM(R25:R29) -> 0
B31: 立 场
B32: 名称 | F32: 类型 | H32: 数值 | I32: 具体效果 | Q32: 重量 | R32: 花费
Q35: =SUM(R33:R34) -> 0
B36: 护 甲 与 装 备
B37: 名称 | F37: 具体效果 | Q37: 重量 | R37: 花费
Q50: =SUM(R38:R49) -> 0
B51: 物 品
B52: 名称 | F52: 具体 | O52: 基重 | P52: 数量 | Q52: 重量 | R52: 花费
B53: 背包 | Q53: =IF(OR(ISBLANK(P53),ISBLANK(O53)),"",P53*O53)
Q54: =IF(OR(ISBLANK(P54),ISBLANK(O54)),"",P54*O54)
Q55: =IF(OR(ISBLANK(P55),ISBLANK(O55)),"",P55*O55)
Q56: =IF(OR(ISBLANK(P56),ISBLANK(O56)),"",P56*O56)
Q57: =IF(OR(ISBLANK(P57),ISBLANK(O57)),"",P57*O57)
Q58: =IF(OR(ISBLANK(P58),ISBLANK(O58)),"",P58*O58)
Q59: =IF(OR(ISBLANK(P59),ISBLANK(O59)),"",P59*O59)
Q60: =IF(OR(ISBLANK(P60),ISBLANK(O60)),"",P60*O60)
Q61: =IF(OR(ISBLANK(P61),ISBLANK(O61)),"",P61*O61)
Q62: =IF(OR(ISBLANK(P62),ISBLANK(O62)),"",P62*O62)
Q63: =IF(OR(ISBLANK(P63),ISBLANK(O63)),"",P63*O63)
Q64: =IF(OR(ISBLANK(P64),ISBLANK(O64)),"",P64*O64)
Q65: =IF(OR(ISBLANK(P65),ISBLANK(O65)),"",P65*O65)
... Q67: =IF(OR(ISBLANK(P67),ISBLANK(O67)),"",P67*O67)
Q68: =SUM(R53:R67) -> 0
B69: 同伴
...

Sheet 灵能
B2: 持有情况 | K2: 灵能相关速查 | Q2: 施法聚焦
B3: 类别 | C3: 次级 | D3: 生化 | E3: 预言 | F3: 操火 | G3: 遥感 | H3: 传心 | I3: 巫术 | J3: 其他 | K3: 优异灵能 | M3: 灵能等级 | O3: 房规加成 | Q3: DH施法
B4: 数量 | Q4: 束缚 | R4: 自由 | S4: 引导
B5: 精通 | K5: 专注/法器 | M5: 灵能感应 | O5: WP | P5: WB | Q5: =ROUND(R5/2,0) -> 0 | R5: =M4 -> 0 | S5: =R5+3 -> 3
B6: 专攻 | O6: =人物!K20 -> 0 | P6: =人物!L20 -> 0 | Q6: RT施法
B7: 额外 | K7: 其他天赋 | Q7: 束缚 | R7: 自由 | S7: 引导
B8: 共计 | C8: =IF(M4="","",IF(C6="√",2,0)+P6+K4+C7) | D8: =IF(M4="","",IF(D6="√",2,0)+P6+K4+D7) | E8: =IF(M4="","",IF(E6="√",2,0)+P6+K4+E7) | F8: =IF(M4="","",IF(F6="√",2,0)+P6+K4+F7) | G8: =IF(M4="","",IF(G6="√",2,0)+P6+K4+G7) | H8: =IF(M4="","",IF(H6="√",2,0)+P6+K4+H7) | I8: =IF(M4="","",IF(I6="√",2,0)+P6+K4+I7) | J8: =IF(M4="","",IF(J6="√",2,0)+P6+K4+J7) | Q8: =Q5*5+O6 -> 0 | R8: =R5*5+O6 -> 0 | S8: =S5*5+O6 -> 15
B10: ↓搜索框
B11: 灵能类别 | H11: 灵能名称 | N11: 加值 | P11: 束缚 | Q11: {=IF(M4="","",Q5&"D10+"&_xlfn.SWITCH(E11,"次级灵能",C8,"生化学科",D8,"预言学科",E8,"操火学科",F8,"遥感学科",G8,"传心学科",H8,"高阶秘仪",I8,"其他灵能",J8,P6+K4))}
P12: 自由 | Q12: {=IF(M4="","",R5&"D10+"&_xlfn.SWITCH(E11,"次级灵能",C8,"生化学科",D8,"预言学科",E8,"操火学科",F8,"遥感学科",G8,"传心学科",H8,"高阶秘仪",I8,"其他灵能",J8,P6+K4))}
P13: 引导 | Q13: {=IF(M4="","",S5&"D10+"&_xlfn.SWITCH(E11,"次级灵能",C8,"生化学科",D8,"预言学科",E8,"操火学科",F8,"遥感学科",G8,"传心学科",H8,"高阶秘仪",I8,"其他灵能",J8,P6+K4))}
B14: Ps：可以在灵能大全表最末自己手动添加房规灵能，会自动同步
B15: 灵 能 详 情
B16: 灵能名称 | E16: 灵能类别 | H16: 阈值 | K16: 聚焦 | N16: 维持 | Q16: 范围
B17: =IFERROR(VLOOKUP(K11,灵能表[],1,0),"") | E17: =IFERROR(VLOOKUP(K11,灵能表[],2,0),"") | H17: =IFERROR(VLOOKUP(K11,灵能表[],3,0),"") | K17: =IFERROR(VLOOKUP(K11,灵能表[],4,0),"") | N17: =IFERROR(VLOOKUP(K11,灵能表[],5,0),"") | Q17: =IFERROR(VLOOKUP(K11,灵能表[],6,0),"")
B18: =IFERROR(VLOOKUP(K11,灵能表[],7,0),"")
B30: 超量释放 | E30: =IFERROR(VLOOKUP(K11,灵能表[],8,0),"")
B35: 次 级 灵 能
B36: 次级灵能
B43: 次级秘仪
B46: 学 科 灵 能
B57: 其 他 灵 能

Sheet 数据导入
B2: 角色卡导入（泛用） | T2: 表格制作者
B3: 右键下格，点击“复制”，并在下方的TXT栏“粘贴”就可以导出文本，然后再选中文本，复制到最上方显示框，然后再剪切进QQ可以避免黏贴的是图片的问题。 也可以直接复制下格，复制进一个TXT文本。 | T3: 排名不分先后
T4: 勒
T5: 迮越
B6: =人物!A36 -> .st格斗0近战0射击0远程0力量0坚韧0敏捷0智力0感知0意志0交际0生命值生命值上限0命运点命运点上限威胁0恐吓0攀爬0运动0游泳0酗酒0狂饮0躲藏0闪避0潜行0估价0逻辑0赌博0警觉0搜查0搜索0察言观色0交易0欺诈0搜集信息0伪装0吸引0扯淡0指挥0 | T6: 晨星
T7: 一壶
T8: 五三点九
T9: IAN
T10: 浣熊旅記
B12: 复制上表↑粘贴在这里↓，然后再复制文本
B20: 更新日志
B21: v1.31 | D21: 添加了更多弹药并并入自动化中。 优化了1.3版本更新后，弹药计算总数时只填充数量会导致总数显示错误的bug
B23: v1.4 | D23: 添加了机机风味美化，修复了角色卡没有纯洁印记的漏洞 增加了天赋及技能详情速查表，购物表并加入了自动化，添加住宿和医疗表，以及添加了机械神甫晋升表。
B26: v2.0 | D26: 在v1.4基础上重构版面；新增同时也删减合并了部分自动化 新增了巫术 为便于区分，半自动轻量版系角色卡以2.x开头
B29: v2.1 | D29: 细节优化

Sheet 灵能大全
B2: 灵能名称 | C2: 灵能类别 | D2: 阈值 | E2: 聚焦 | F2: 维持 | G2: 范围 | H2: 能力 | I2: 超量释放
B3: 鼓舞氛围 | C3: 次级灵能 | D3: 6 | E3: 完整动作 | F3: 可 | G3: 自身 | H3: 这是个好的灵能，它让你看上去很好，所有看到你的人都会忍不住想对你说好话，这很好。另外，看到你的人会觉得充满自信，以至于对抗恐惧和压制的检定 +20。 | I3: /
B4: 减缓痛苦 | C4: 次级灵能 | D4: 8 | E4: 部分动作 | F4: 否 | G4: 10m | H4: 范围内你指定的一个生物（也可以是你自己）移除 1 级虚弱。 | I4: 每超过阀值 5 点，额外移除 1 级虚弱。
B5: 痉挛 | C5: 次级灵能 | D5: 7 | E5: 部分动作 | F5: 否 | G5: 50m | H5: 你可以瞬间使目标肌肉痉挛。目标可以进行意志检定抵抗此效果，失败会全身发痒，陷入一阵无法控制的痉挛，并立刻倒地。如果目标持有射击武器，该武器会走火，目标正常进行 BS 检定并击中最接近的人。 | I5: 每超过阀值 5 点，你可以多指定一个目标，或者将意志检定难度提高一级。
B6: 武器故障 | C6: 次级灵能 | D6: 8 | E6: 完整动作 | F6: 否 | G6: 50m | H6: 用你的意志干扰机魂，范围内你指定的一件不具有原始特性的武器自动发生故障。武器故障可以通过正常方法排除。注意机械神教对这种做法很反感，对这种灵能者往往持不信任态度。 | I6: 每超过阀值 5 点，影响范围增加10m，或者多指定一件武器。
B7: 医疗者 | C7: 次级灵能 | D7: 7 | E7: 完整动作 | F7: 否 | G7: 10m | H7: 该灵能只能作用于范围内的一个自愿目标（包括你自己），并使其恢复 1d5 点伤害（优先恢复致命伤害）。但是反复使用这种治疗手段存在危险，人体会开始抵制亚空间的能量。如果目标在六小时之内再次被施以此灵能，他必须进行坚韧检定，否则会受到而不是恢复1d5 伤害，该伤害无视坚韧加值和护甲防护。 | I7: /
B8: 把戏 | C8: 次级灵能 | D8: 5 | E8: 部分动作 | F8: 可 | G8: 自身 | H8: 你巧妙地影响身边的“场”，让自己在游戏中作弊的技巧更为高超。灵能生效期间，赌博技能将变为你的基本技能，且得到二级精通（+20）。如果你已经掌握了赌博技能，则该技能检定 +20。但如果你在赌博技能上已经有任何一级精通，该灵能无效，因为你已经达到这个水准了。 | I8: /
B9: 白噪音 | C9: 次级灵能 | D9: 8 | E9: 完整动作 | F9: 可 | G9: 10m | H9: 让区域内充满亚空间干扰，使区域内的任何目标都难以被侦测。尝试用灵能手段或技术手段对该区域内任何目标进行侦测的检定变为艰难(-20)。如果侦测手段不需要检定，那么侦测者需要进行一个常规(+10)意志检定(使用灵能手段)或常规(+10)智力检定(使用科技手段)。 | I9: 每超过阀值 5 点，影响范围增加10m。
B10: 爆炸闪光 | C10: 次级灵能 | D10: 6 | E10: 部分动作 | F10: 否 | G10: 20m | H10: 你制造出一阵闪光爆炸，范围内的任何人都要进行一次常规（+20）意志检定，失败则眩晕 1 轮。 | I10: 每超过阀值 10 点，检定难度提升一级。
B11: 变色龙 | C11: 次级灵能 | D11: 7 | E11: 部分动作 | F11: 可 | G11: 自身 | H11: 让自己身体颜色与环境一致。躲藏+30，针对你的射击 BS-20。 | I11: /
B12: 抵抗附身 | C12: 次级灵能 | D12: 6 | E12: 反射动作 | F12: 否 | G12: 自身 | H12: 建立精神守护保卫自己的意志。接下来的一小时之内，抵抗恶魔的附身时，你可以重投任何失败的意志检定。 | I12: /
B13: 凋零 | C13: 次级灵能 | D13: 6 | E13: 完整动作 | F13: 否 | G13: 3d10m | H13: 你引发一阵恶毒的波动席卷四周，使范围内的所有“正常”植物凋零死亡。 | I13: 每超过阀值 5 点，影响范围增加1d10m。
B14: 非凡精准 | C14: 次级灵能 | D14: 8 | E14: 部分动作 | F14: 否 | G14: 自身 | H14: 用亚空间的力量引导自己瞄准。到你的下一回合结束，你所做的任何 BS 检定 +30。 | I14: /
... B114: 恶魔咒阵 | C114: 高阶秘仪 | D114: 23 | E114: 完整动作 | F114: 否 | G114: 50m | H114: 通过编织亚空间能量的术式，巫师可以尝试驱退、困缚并夺取对恶魔实体的控制权。 施展成功后，巫师可与目标恶魔生物进行意志对抗检定，以此对其施加厄咒。或者，如果目标恶魔的意志属性为 50 或更低，则巫师可改为强制进行一次恶魔掌控检定来支配它。 特殊：这项能力仅能影响同时具有恶魔特性和亚空间不稳定特性的实体。 | I114: 每超过阈值 5 点，巫师在意志对抗和恶魔掌控检定上便获得 +10 加值。
B115: 恶毒诅咒 | C115: 高阶秘仪 | D115: 特殊 | E115: 完整动作 | F115: 否 | G115: 视线范围内 | H115: 阈值：祸祟 16；致盲 20；催命 23 你祈求扭曲交缠的恶性能量，为受害者带去灾祸与诅咒。此处列出了三种不同的诅咒形式，当然，世上的诅咒形式显然不止于此。无论面对何种诅咒，受害者均可尝试通过一次难度为挑战（+0）的意志检定，以此抵抗诅咒效果。 祸祟 Hex：受害者饱受厄运缠身、蚀骨寒意与超自然的恐惧折磨。在接下来的 1d5 小时内，受害者的所有属性检定与技能检定均承受 -10 减值。若抵抗此能力的检定失败度为 3 及以上，受害者还必须额外在表 8-4：震惊（Shock）上掷骰（见《黑暗异端》第 233 页），此情形被视作亚空间惊吓。 致盲 Blindness：受害者的双眼被白内障填满，泣出血泪，陷入失明状态，持续 1d5 小时。若抵抗此巫术的检定失败度为 3 及以上，受害者的双眼会在血雨飞溅中被摧毁，对头部造成 1d10 R 伤害，并且会永久失明（若其幸存，则需更换假眼）。双眼被摧毁还会带给受害者 1d10 点失心。 催命 Death：通过遏停心跳、引爆血管、撕裂内脏以及其他种种可怖方式，此诅咒的威力足以使人丧失行动能力，甚至致人死亡。受害者遭受 3d10+10 点坚韧伤害（若其具有超自然坚韧（x2）等特性，则伤害减半）。受害者的坚韧降至 0 点时，其立即死亡。若此诅咒的受害者存活下来，则坚韧伤害可如常治疗。 注意：因诅咒而死时，受害者可以燃烧 1 命运点来避免暴毙，并恢复 1d5 坚韧。但受害者会陷入昏迷状态，亟需紧急救治。 特殊：每次施展诅咒时，巫师必须通过一次难度为挑战（+0）的意志检定，否则其获得 1d5 点堕落。 | I115: 每超过阈值 5 点，受害者抵抗诅咒的检定难度便提高一级，最高难度为艰巨（-30）。
B116: 地狱爆破 | C116: 高阶秘仪 | D116: 22 | E116: 部分动作 | F116: 否 | G116: 5m x 意志加值 | H116: 使用此能力时，你可以从亚空间引导能量，向受害者投掷一团纯粹的毁灭性爆流，将其点燃并炸成碎片。如同远程攻击一般，你进行一次远程技巧（BS）检定以命中目标。检定成功时，你的攻击造成 1d10+WB E 伤害。这次伤害视为具备亚空间武器特性，因此可以穿透大多数护甲与防御。 | I116: 每超过阈值 10 点，便额外造成 1d10 点伤害。
B117: 黑暗导能 | C117: 高阶秘仪 | D117: 25 | E117: 完整动作 | F117: 可 | G117: 20 米半径 | H117: 巫师从亚空间中汲取扭曲力量，用以增强和维系范围内的恶魔生物，巩固恶魔在现实世界的存在，并强化其力量。 作用范围内，任何拥有恶魔特性的生物获得再生特性，其先攻 +1，并在抵抗亚空间不稳定时获得 +10 加值。 特殊：巫师需要为引导这些邪恶能量支付代价。维持灵能的每一轮，施术者都必须通过一次难度为困难（-10）的坚韧检定，否则将失去 1 点承伤。 | I117: 每超过阈值 10 点，范围半径增加 10 米。
B118: 恶意风暴 | C118: 高阶秘仪 | D118: 18 | E118: 完整动作 | F118: 可 | G118: 50 米半径 | H118: 巫师借助亚空间中那些经由灵能回响而传播开的恶意、偏执与仇恨，将突如其来的狂怒、恐慌与杀意，灌注进毫无防备之人的心智中去，并由此引发致命后果。这股情绪浪潮足以将一群普通人变成施暴的狂徒，引起大规模的群体癫狂与血腥暴乱。在能力生效期间，身处范围内的所有活物，每轮必须通过一次难度为挑战（+0）的意志检定，否则便会陷入极度危险且充满暴力的狂怒状态。依据其各自的心智状况，他们要么会疯狂攻击任何触手可及的人，要么会因极度恐惧而四散奔逃。如果受害者屈从于这项能力，其所带来的直接影响将持续到维持结束，再加上额外 1d10 轮。 这项能力属于灵能攻击，同时也被视为恐惧效果，因此能够抵抗恐惧的天赋和特性，对这项能力同样有效。 | I118: 每超过阈值 10 点，范围半径翻倍。
B119: 时间扭曲 | C119: 高阶秘仪 | D119: 20 | E119: 完整动作 | F119: 可 | G119: 自身 | H119: 巫师使自己与周围现实及时间的流动略微错相。巫师的身形变得模糊且飘忽不定，其过去与未来各种可能行动的阴影相互重叠，如幽灵般环绕其身周。 能力生效期间，巫师变得极难被击中，任何对其发起的攻击检定承受 -20 减值。此外，如果巫师在 1d10 中掷出奇数结果（即1、3、5、7、9），则任何成功命中将被抵消，除非该次攻击使用灵能、来自受祝（Blessed）或神圣（Holy）武器，或是具备亚空间武器特性。 特殊：如果巫师遭受亚空间危险，则时间反冲将撕裂巫师自身，对其造成 3d10 E 伤害。 | I119: 每超过阈值 5 点，此能力在维持中断后，效果额外持续 1 轮。
B120: 创造门扉 | C120: 高阶秘仪 | D120: 28 | E120: 完整动作 | F120: 否 | G120: 5m | H120: 巫师凭空召唤出一道燃烧的门扉。这道门扉可用于将巫师传送至他脑海中能清晰回忆起的任何地方。巫师的玩家必须告知游戏主持人他希望门扉通向何处；游戏主持人随后会根据巫师上次身处该地的时间、其心智状态、周遭环境及专注程度，设定一个适当的难度等级。巫师随后可迈步穿过门扉，并基于该难度等级进行智力检定。若检定通过，则一切顺利。若未通过，游戏主持人将决定一个合适的替代目的地——通常是一个巫师宁愿避开的地方。 特殊：穿越如此亵渎的门户，会让使用者比安全限度更接近亚空间的恐怖。任何穿过门扉者都必须通过一个难度为艰难（-20）的意志检定。若检定失败，该角色必须在亚空间危险表上掷骰。 10 米–100 米：常规（+20）；101 米–1000 米：普通（+10）；星球内的任意地点：挑战（+ 0）；星系内的任意地点：困难（-10）；次星区内的任意地点：艰难（-20）；星区内的任意地点：艰巨（-30） | I120: /
B121: 疫病 | C121: 高阶秘仪 | D121: 20 | E121: 部分动作 | F121: 否 | G121: 5m | H121: 巫师轻蔑地一挥手，便将一场瘟疫降于目标身上。目标开始呕出胆汁与鲜血，皮肤上隆起脓包。此疫病持续轮数等于 1d10 减去目标的坚韧加值。目标在染疫期间，全部属性每轮降低 10 点。若其坚韧降低至零，则目标死亡。 超量释放：每超过阈值 5 点，疫病的持续时间增加 1 轮。 特殊：若一名角色死于疫病，其灵魂将归于瘟疫之主纳垢。倒下的尸体会进一步腐烂，并在 5 轮后作为一只瘟疫使者（Plaguebearer）站起（见《黑暗异端》规则书第 354 页）。瘟疫使者会立即攻击附近的任何生物。 | I121: /
B122: 失血术 | C122: 高阶秘仪 | D122: 18 | E122: 部分动作 | F122: 否 | G122: 10m | H122: 巫师朝目标打个响指并吼出一段咒文，使目标的血液沸腾、涌出体外。巫师用意志与目标的坚韧对抗。若对抗成功，目标承受等同于巫师意志加值两倍的伤害（坚韧加值与护甲无法减免此伤害），并会陷入失血状态（见《黑暗异端》规则书第 211 页）。 | I122: /
B123: 颅骨连枷 | C123: 高阶秘仪 | D123: 14 | E123: 部分动作 | F123: 可 | G123: 自身 | H123: 巫师以亚空间为索，将亡者的颅骨束缚在一起，打造出一把燃烧着恶意的颅骨连枷。颅骨连枷显现后，其数据与普通连枷相同（见《黑暗异端》规则书第 139 页），但具有亚空间武器特性，能够绕过大多数护甲与防御。任何受到颅骨连枷伤害的目标将获得 1d10 点失心，并且从第二颗颅骨之后算起，每多使用一颗颅骨打造此连枷，便额外造成 1 点失心。 特殊：显然，使用此能力需要巫师拥有至少一颗颅骨。 | I123: /
B124: 燃烧之语 | C124: 高阶秘仪 | D124: 18 | E124: 部分动作 | F124: 否 | G124: 自身 | H124: 巫师张开嘴巴，将其作为亚空间烈焰的门户。此能力造成 1d10+4 E 伤害，并具有 3 点破甲。其效果范围可延伸至 20 米，并具有火焰特性。此外，由于这些火焰的超自然本质，任何被此能力效果影响的目标都会自动着火（on fire）（见《黑暗异端》规则书第 210 页）。 特殊：在此能力施展期间，巫师无法进行口头交流；这可能会阻止巫师施放某些其他能力。 | I124: /
B125: 免疫冲击 | C125: 高阶秘仪 | D125: 24 | E125: 部分动作 | F125: 否 | G125: 自身 | H125: 巫师吞下一颗实弹弹药，以此强化自身躯体，抵御投射物与粗制武器的攻击。巫师必须通过一次坚韧检定。若检定成功，巫师在 1d5 轮内免疫任何冲击伤害（Impact Type Damage）。 | I125: /
B126: 汲食生命 | C126: 高阶秘仪 | D126: 21 | E126: 完整动作 | F126: 否 | G126: 接触 | H126: 巫师将手指插入目标的血肉，吸收其生命力，直至目标仅剩一具干枯的躯壳。这一能力仅能作用于处在眩晕状态或其他无力反抗的目标。每超过阈值 5 点，巫师便恢复 1 点承伤，同时目标的承伤减少 1 点。巫师恢复的承伤数不能超过其原本的承伤上限。如果目标的承伤降低至零，则目标死亡。 | I126: /
B127: 活体武器 | C127: 高阶秘仪 | D127: 24 | E127: 完整动作 | F127: 可 | G127: 自身 | H127: 巫师将混沌的邪秽符号刻入自己的血肉之中，呼唤亚空间重塑其肉身以应对战斗。在能力生效期间，巫师的属性获得以下提升：近战技巧 +20、力量 +20、坚韧 +10、敏捷 +10。此外，巫师在所有先攻检定中获得 +3 加值，获得天生武器特性，且其所有近战攻击均获得撕裂特性。在此等兽性状态下，他的交际降低 10 点。 | I127: /
... B137: 苦痛浩劫 | C137: 其他灵能 | D137: 28 | E137: 完整动作 | F137: 可 | G137: 以苦痛之拥为中心，10 米半径内 | H137: 苦痛之拥（见第 131 页）的受害者每时每刻承受着难以想象的剧痛与绝望。他们在生与死间遭受不死的折磨，一边是恶魔对其灵魂的啃噬，一边是肉体永无止境的消亡。经由亚空间的回响与放大，苦痛之拥的受害者能将这种难耐的折磨施加于他人，产生粉碎性的效果。他们能撕裂其周围的现实，将实体物质、血肉与心智一并击溃。 爆炸范围内的一切事物都将承受 2d10 R 伤害。该伤害无视除力场防护或护符（Field effects or wards）之外的任何护甲，且受创者将被巨大的力量向后击飞（与凶猛投掷灵能等效）。任何在此攻击下幸存的生物都必须通过一次难度为艰难（-20）的恐惧检定，否则将遭受亚空间惊吓。 | I137: 每超过阈值 10 点，范围半径增加 10 米。

Sheet 职业数据
A1: 生涯职业 | B1: 起始资金 | C1: 骰点倍数 | D1: 骰点范围 | E1: 社会阶级 | F1: 王座币/月 | G1: 等级提升
A2: 文研员 | B2: 100 | C2: 1 | D2: D10 | E2: 行伍（卫队士兵） | F2: 50 | G2: 5
A3: 执法者/法务官 | B3: 50 | C3: 2 | D3: D10 | E3: 仆役（法务官、灵能者） | F3: 70 | G3: 7
A4: 杀手 | B4: 120 | C4: 3 | D4: D10 | E4: 学者（文研员） | F4: 100 | G4: 10
A5: 牧师 | B5: 300 | C5: 5 | D5: D10 | E5: 商人（杀手） | F5: 120 | G5: 12
A6: 卫队士兵 | B6: 70 | C6: 1 | D6: D10 | E6: 技术（技术神甫） | F6: 150 | G6: 15
A7: 帝国灵能者 | B7: 50 | C7: 1 | D7: D5 | E7: 宗教（牧师） | F7: 200 | G7: 20
A8: 流氓 | B8: 10 | C8: 1 | D8: D5 | E8: 贵族 | F8: 500 | G8: 50
A9: 技术神甫 | B9: 150 | C9: 1 | D9: D10
A10: 战斗修女

Sheet 人物数据
A1: 出目 | B1: 预言 | C1: SB+TB | D1: 携带 | E1: 举起 | F1: 拖拽 | G1: 缩写 | H1: AB | I1: 部分移动 | J1: 完整移动 | K1: 冲刺 | L1: 奔跑 | M1: 每分钟 | N1: 每小时 | O1: 每天 | P1: 体型 | Q1: 检定调整 | R1: 起源 | S1: {=_xlfn.UNIQUE(灵能表[灵能类别])} -> 次级灵能 | T1: {=IFERROR(_xlfn._xlws.FILTER(灵能表[灵能名称],灵能表[灵能类别]=灵能!E11),"")}
A2: 1 | B2: “外表的变异，揭示着内心的腐化。” 以一个次级变异状态开始游戏。 | C2: 0 | D2: 0.9 | E2: 2.25 | F2: 4.5 | G2: WS | H2: 0 | I2: 0 | J2: 0 | K2: 0 | L2: =6*H2 -> 0 | M2: 12m | N2: 0.75km | O2: 7km | P2: 微小 | Q2: -30 | R2: 野蛮世界 | S2: 生化学科
A3: 2 | B3: “只有疯狂者才有成功所需的力量，只有成功者才有权定义何为理智。”以2点失心点数状态开始游戏。 | C3: 1 | D3: 2.25 | E3: 4.5 | F3: 9 | G3: BS | H3: 1 | I3: 1 | J3: 2 | K3: 3 | L3: =6*H3 -> 6 | M3: 24m | N3: 1.5km | O3: 15km | P3: 超小 | Q3: -20 | R3: 帝国世界 | S3: 预言学科
A4: 3 | B4: “只有疯狂者才有成功所需的力量，只有成功者才有权定义何为理智。”以2点失心点数状态开始游戏。 | C4: 2 | D4: 4.5 | E4: 9 | F4: 18 | G4: S | H4: 2 | I4: 2 | J4: 4 | K4: 6 | L4: =6*H4 -> 12 | M4: 48m | N4: 3km | O4: 30km | P4: 小型 | Q4: -10 | R4: 巢都世界 | S4: 操火学科
A5: 4 | B5: “罪恶越是深藏于内心，越是能够腐化人的一切。” 以3点堕落点数开始游戏。 | C5: 3 | D5: 9 | E5: =2*D5 -> 18 | F5: =2*E5 -> 36 | G5: T | H5: 3 | I5: 3 | J5: 6 | K5: 9 | L5: =6*H5 -> 18 | M5: 72m | N5: 4km | O5: 40km | P5: 中型 | Q5: 0 | R5: 虚空 | S5: 遥感学科
A6: 5 | B6: “罪恶越是深藏于内心，越是能够腐化人的一切。” 以3点堕落点数开始游戏。 | C6: 4 | D6: 18 | E6: 36 | F6: 72 | G6: Ag | H6: 4 | I6: 4 | J6: 8 | K6: 12 | L6: =6*H6 -> 24 | M6: 96m | N6: 6km | O6: 60km | P6: 大型 | Q6: 10 | R6: 铸造世界 | S6: 传心学科
A7: 6 | B7: “罪恶越是深藏于内心，越是能够腐化人的一切。” 以3点堕落点数开始游戏。 | C7: 5 | D7: 27 | E7: 54 | F7: 108 | G7: Int | H7: 5 | I7: 5 | J7: 10 | K7: 15 | L7: =6*H7 -> 30 | M7: 120m | N7: 7km | O7: 70km | P7: 超大 | Q7: 20 | R7: 被洗脑者 | S7: 次级秘仪
A8: 7 | B8: “罪恶越是深藏于内心，越是能够腐化人的一切。” 以3点堕落点数开始游戏。 | C8: 6 | D8: 36 | E8: 72 | F8: 144 | G8: Per | H8: 6 | I8: 6 | J8: 12 | K8: 18 | L8: =6*H8 -> 36 | M8: 144m | N8: 9km | O8: 90km | P8: 巨大 | Q8: 30 | R8: 贵族出身 | S8: 高阶秘仪
A9: 8 | B9: “所谓清白无辜，只是虚妄的假象。” 以1点失心点和1点堕落点状态开始游戏。 | C9: 7 | D9: 45 | E9: 90 | F9: 180 | G9: WP | H9: 7 | I9: 7 | J9: 14 | K9: 21 | L9: =6*H9 -> 42 | M9: 168m | N9: 10km | O9: 100km | R9: 忠嗣学院 | S9: 其他灵能
A10: 9 | B10: “黑暗的迷梦徘徊在心门之内。” 以2点堕落点数开始游戏。 | C10: 8 | D10: 56 | E10: 112 | F10: 224 | G10: Fel | H10: 8 | I10: 8 | J10: 16 | K10: 24 | L10: =6*H10 -> 48 | M10: 192m | N10: 12km | O10: 120km | R10: 圣殿世界
A11: 10 | B11: “黑暗的迷梦徘徊在心门之内。” 以2点堕落点数开始游戏。 | C11: 9 | D11: 67 | E11: 134 | F11: 268 | H11: 9 | I11: 9 | J11: 18 | K11: 27 | L11: =6*H11 -> 54 | M11: 216m | N11: 13km | O11: 130km | R11: 辅秘修会门徒
A12: 11 | B12: “黑暗的迷梦徘徊在心门之内。” 以2点堕落点数开始游戏。 | C12: 10 | D12: 78 | E12: 156 | F12: 312 | H12: 10 | I12: 10 | J12: 20 | K12: 30 | L12: =6*H12 -> 60 | M12: 240m | N12: 14km | O12: 140km | R12: 修道院的培养
A13: 12 | B13: “与天谴之堕落相比，子弹带来的痛苦无异极乐。” 坚韧+1。 | C13: 11 | D13: 90 | E13: 180 | F13: 360 | R13: 卡利西斯战斗舰队
A14: 13 | B14: “与天谴之堕落相比，子弹带来的痛苦无异极乐。” 坚韧+1。 | C14: 12 | D14: 112 | E14: 224 | F14: 448 | R14: 黄昏星
A15: 14 | B15: “与天谴之堕落相比，子弹带来的痛苦无异极乐。” 坚韧+1。 | C15: 13 | D15: 225 | E15: 450 | F15: 900 | R15: 炮铜城/铁灰城
A16: 15 | B16: “与天谴之堕落相比，子弹带来的痛苦无异极乐。” 坚韧+1。 | C16: 14 | D16: 337 | E16: 674 | F16: 1348 | R16: 玛卡贝斯五号
A17: 16 | B17: “在外种族异形得以开口欺骗之前将其处死。” 敏捷+2。 | C17: 15 | D17: 450 | E17: 900 | F17: 1800 | R17: 锡诺菲亚
A18: 17 | B18: “在外种族异形得以开口欺骗之前将其处死。” 敏捷+2。 | C18: 16 | D18: 675 | E18: 1350 | F18: 2700 | R18: 沃尔格芬克斯
A19: 18 | B19: “在外种族异形得以开口欺骗之前将其处死。” 敏捷+2。 | C19: 17 | D19: 900 | E19: 1800 | F19: 3600 | R19: 凋零学院
A20: 19 | B20: “所谓事实，不过是一种主观虚饰。” 智力+3，以3点堕落点数开始游戏。 | C20: 18 | D20: 1350 | E20: 2700 | F20: 5400 | R20: 黑暗要塞
A21: 20 | B21: “所谓事实，不过是一种主观虚饰。” 智力+3，以3点堕落点数开始游戏。 | C21: 19 | D21: 1800 | E21: 3600 | F21: 7200 | R21: 巢都变种人
A22: 21 | B22: “所谓事实，不过是一种主观虚饰。” 智力+3，以3点堕落点数开始游戏。 | C22: 20 | D22: 2250 | E22: 4500 | F22: 9000 | R22: 马尔菲的诅咒血脉
A23: 22 | B23: “了解变异者；消灭变异者。” 感知+2。 | R23: 自定义起源
A24: 23 | B24: “了解变异者；消灭变异者。” 感知+2。
A25: 24 | B25: “了解变异者；消灭变异者。” 感知+2。
A26: 25 | B26: “了解变异者；消灭变异者。” 感知+2。
A27: 26 | B27: “了解变异者；消灭变异者。” 感知+2。
A28: 27 | B28: “即使是一无所有的人，依然可以贡献自己的生命。” 力量+2。
A29: 28 | B29: “即使是一无所有的人，依然可以贡献自己的生命。” 力量+2。
A30: 29 | B30: “即使是一无所有的人，依然可以贡献自己的生命。” 力量+2。
A31: 30 | B31: “即使是一无所有的人，依然可以贡献自己的生命。” 力量+2。
A32: 31 | B32: “如果一项任务值得做，它值得你付出生命。” 得到狂暴天赋。
A33: 32 | B33: “如果一项任务值得做，它值得你付出生命。” 得到狂暴天赋。
A34: 33 | B34: “如果一项任务值得做，它值得你付出生命。” 得到狂暴天赋。
A35: 34 | B35: “只有死亡才是职责终结之时。” 承伤+1。
... A101: 100 | B101: “不要问为什么尽职，只问怎样去做。” 格斗能力+2，射击能力+2。
