Workbook
Name 操火: #REF!
Name 传心: #REF!
Name 活力: #REF!
Name 遥感: #REF!
Name 预言: #REF!
Name 预言: 灵能大全!$C$64:$I$73
Name 次级灵能: 灵能大全!$C$3:$I$50
Name 文研员: 职业数据!$K$2:$K$13
Name 杀手: 职业数据!$M$2:$M$12
Name 牧师: 职业数据!$N$2:$N$12
Name 卫队士兵: 职业数据!$O$2:$O$15
Name 帝国灵能者: 职业数据!$P$2:$P$14
Name 流氓: 职业数据!$Q$2:$Q$12
Name 技术神甫: 职业数据!$R$2:$R$12
Name 法务官: 职业数据!$L$2:$L$12
Name 战斗修女背景包: 职业数据!$R$19:$R$30
Name 牧师背景包: 职业数据!$M$19:$M$37
Name 卫队士兵背景包: 职业数据!$N$19:$N$37
Name 帝国灵能者背景包: 职业数据!$O$19:$O$31
Name 技术神甫背景包: 职业数据!$Q$19:$Q$34
Name 杀手背景包: 职业数据!$L$19:$L$36
Name 法务官背景包: 职业数据!$K$19:$K$37
Name 文研员背景包: 职业数据!$J$19:$J$39
Name 流氓背景包: 职业数据!$P$19:$P$39

Sheet 人物
AC1: =".st"&"格斗"&K10&"射击"&K11&"力量"&K12&"坚韧"&K13&"敏捷"&K14&"智力"&K15&"感知"&K16&"意志"&K17&"交际"&K18&"生命值"&R28&"生命值上限"&P28&"命运点"&M17&"命运点上限"&M12&"威胁"&I42&"恐吓"&I42&"攀爬"&I43&"运动"&I43&B44&I44&"酗酒"&I45&"狂欢"&I45&B46&I46&B47&I47&B48&I48&B49&I49&B50&I50&B51&I51&B52&I52&"搜查"&I53&"搜索"&I53&B54&I54&B55&I55&B56&I56&B57&I57&B58&I58&B59&I59&B60&I60&B61&I61&A65&A68&A70&A72&A75&A78&A80&A82&A87&A89 -> .st格斗0射击0力量0坚韧0敏捷0智力0感知0意志0交际0生命值生命值上限0命运点命运点上限威胁0恐吓0攀爬0运动0游泳0酗酒0狂欢0躲藏0闪避0潜行0估价0逻辑0赌博0警觉0搜查0搜索0察言观色0交易0欺诈0搜集信息0伪装0吸引0扯淡0指挥0 | AD1: 审判庭汇款单（自动计算工资小工具）
B2: 玩家 | H2: 角色 | J2: 填入角色名称 | T2: 资金 | U2: 是否启用月工资 | X2: 否 | Z2: 每月 | AA2: =IFERROR(IF(X2="是",AR3,0),"") -> 0 | AD2: 社会阶级 | AI2: 当前等级 | AK2: 等级提升 | AM2: 当月工资 | AO2: 已发放工资月数 | AR2: 工资总额
B3: 生涯职业 | H3: 生日 | L3: 月 | N3: 日 | P3: 年龄 | U3: 行动经费 | Z3: 已用 | AA3: =SUM(武备!AB4:AB7)+SUM(武备!T4:T7)+SUM(武备!AB10:AB17)+SUM(武备!AB20:AB25)+SUM(武备!AB28:AB32)+SUM(武备!AB35:AB40)+SUM(武备!AB43:AB56)+SUM(武备!I75:I92)+SUM(武备!AJ65:AJ104)+SUM(武备!AO65:AO104)-SUM(武备!AJ22:AJ61)-SUM(武备!AO22:AO61) -> 0 | AI3: =IF(AD3="","",IF(N4>=10000,8,IF(N4>=8000,7,IF(N4>=6000,6,IF(N4>=3000,5,IF(N4>=2000,4,IF(N4>=1000,3,IF(N4>=500,2,IF(N4>=1,1,""))))))))) | AK3: =IF(AD3="","",VLOOKUP(AD3,职业数据!E:G,3,FALSE)) | AM3: =IF(AD3="","",VLOOKUP(AD3,职业数据!E2:G8,2,FALSE)+(AI3-1)*VLOOKUP(AD3,职业数据!E2:G8,3,FALSE)) | AO3: =IF(AD3="","",MAX(0,INT((MIN(N4,15000)-400)/400))) | AR3: {=IF(AD3="","",IF(AO3=0,0,SUMPRODUCT(--((ROW(INDEX(职业数据!E:E,1):INDEX(职业数据!E:E,AO3))*400+400)<=MIN(N4,15000)),VLOOKUP(AD3,职业数据!E2:G8,2,FALSE)+(LOOKUP(ROW(INDEX(职业数据!E:E,1):INDEX(职业数据!E:E,AO3))*400+400,{0,500,1000,2000,3000,6000,8000,10000},{0,1,2,3,4,5,6,7})*VLOOKUP(AD3,职业数据!E2:G8,3,FALSE)))))}
B4: 当前阶级 | H4: 等级 | L4: 经验 | M4: 持有 | P4: 已用 | Q4: =I19+R62+Z65+Z80+R91+AA120 -> 0 | U4: 其他收入 | Z4: 剩下 | AA4: =IFERROR(W4+W3+AR7-AA3,"")
AD5: 起始资金
B6: 状态 | D6: 身高 | G6: 虹膜 | J6: 发色 | M6: 预言 | N6: 投掷 | O6: 预言 | X6: 影响 | AD6: 生涯职业 | AI6: 起始资金骰点 | AR6: 总金额
D7: 体重 | G7: 肤色 | J7: 发型 | O7: =IF(N7="","",VLOOKUP(N7,人物数据!A:C,2,FALSE)) | X7: =IF(N7="","",VLOOKUP(N7,人物数据!A:C,3,FALSE)) | AI7: =IF(AD7="","",VLOOKUP(AD7,职业数据!A:D,2,FALSE)) | AK7: + | AL7: =IF(AD7="","",VLOOKUP(AD7,职业数据!A:D,3,FALSE)) | AM7: =IF(AD7="","",VLOOKUP(AD7,职业数据!A:D,4,FALSE)) | AN7: （ | AO7: 1 | AP7: ） | AQ7: = | AR7: =IF(AD7="","",AI7+AL7*AO7)
AN8: ↑↑↑骰子自己丢
B9: 属性情况 | D9: 基础 | E9: 超然 | F9: 备注 | G9: 加成 | H9: 训练 | I9: 消耗XP | J9: 减值 | K9: 最终 | L9: 加值 | M9: 命 运 点 | N9: 失心 | Q9: 堕落 | T9: 角色头像 | V9: 这里可以有头像
B10: 格斗 WS | E10: 1 | K10: =D10+G10+H10-J10 -> 0 | L10: =INT(K10/10)*E10 -> 0 | S10: 80 | AD10: 颅骨记账（不并入自动化，可用可不用）
B11: 射击 BS | E11: 1 | K11: =D11+G11+H11-J11 -> 0 | L11: =INT(K11/10)*E11 -> 0 | S11: 81 | AD11: 购买 | AF11: 花费 | AH11: 备注 | AJ11: 售出 | AL11: 收入 | AN11: 备注 | AP11: 额外收入 | AR11: 备注
B12: 力量 S | E12: 1 | K12: =D12+G12+H12-J12 -> 0 | L12: =INT(K12/10)*E12 -> 0 | S12: 82
B13: 坚韧 T | E13: 1 | K13: =D13+G13+H13-J13 -> 0 | L13: =INT(K13/10)*E13 -> 0 | S13: 83
B14: 敏捷 Ag | E14: 1 | K14: =D14+G14+H14-J14 -> 0 | L14: =INT(K14/10)*E14 -> 0 | M14: 剩 余 | S14: 84
B15: 智力 Int | E15: 1 | K15: =D15+G15+H15-J15 -> 0 | L15: =INT(K15/10)*E15 -> 0 | S15: 85
B16: 感知 Per | E16: 1 | K16: =D16+G16+H16-J16 -> 0 | L16: =INT(K16/10)*E16 -> 0 | S16: 86
B17: 意志 WP | E17: 1 | K17: =D17+G17+H17-J17 -> 0 | L17: =INT(K17/10)*E17 -> 0 | S17: 87
B18: 交际 Fel | E18: 1 | K18: =D18+G18+H18-J18 -> 0 | L18: =INT(K18/10)*E18 -> 0 | S18: 88
I19: =SUM(I10:I18) -> 0 | W19: 角色
B20: 移动 | D20: 部分 | F20: 完整 | H20: 冲锋 | J20: 奔跑 | L20: 每分钟 | N20: 每小时 | P20: 每天 | R20: 备注 | T20: 致命伤情况
B21: 徒步 | D21: =L14 -> 0 | F21: =D21*2 -> 0 | H21: =D21*3 -> 0 | J21: =D21*6 -> 0 | L21: =VLOOKUP(L14,人物数据!I2:P12,6,FALSE) -> 12m | N21: =VLOOKUP(L14,人物数据!I2:P12,7,FALSE) -> 0.75km | P21: =VLOOKUP(L14,人物数据!I2:P12,8,FALSE) -> 7km | R21: — | T21: 头部 0-1 | Y21: 躯干 31-70
B22: 飞跑 | D22: —— | F22: —— | H22: —— | J22: =J21*2 -> 0 | L22: —— | N22: —— | P22: —— | R22: — | T22: 右手 11-20 | Y22: 左手 21-30
T23: 左腿 86-00 | Y23: 左腿 71-85
B24: 先攻 | D24: 基础 | F24: 谨小慎微 | H24: 闪电反射 | J24: 巢都出身 | L24: 其他 | N24: 最终 | T24: 其他 | Y24: 其他
D25: =L14 -> 0 | F25: 否 | H25: 否 | J25: 否 | L25: 暂无 | N25: ="1D10+"&(IF(H25="是",D25*2,D25)+IF(F25="是",2,0)+IF(J25="是",1,0)) -> 1D10+0
T26: 负重（单位：kg）
B27: 承伤和防护情况（简） | T27: 负重上限 | V27: =VLOOKUP(V29,人物数据!D2:G22,2,FALSE) -> 0.9 | X27: 当前负重 | Z27: =SUM(武备!S4:S7)+SUM(武备!Z11:Z17)+SUM(武备!AA20:AA25)+SUM(武备!AA28:AA32)+SUM(武备!AA35:AA40)+SUM(武备!AA43:AA56) -> 0
B28: 承伤 | D28: 基础 | F28: 加成 | H28: 备注 | J28: 减值 | L28: 备注 | N28: 最终承伤 | P28: =E28+G28-K28 -> 0 | Q28: 剩余 | T28: 参考值 | V28: SB+TB | X28: 举起 | Z28: 拖拽
B29: 装备数值 | D29: 头部 0-1 | F29: 右臂 11-20 | H29: 左臂 21-30 | J29: 躯干 31-70 | L29: 右腿 71-85 | N29: 左腿 86-00 | P29: 血肉苦弱 | R29: 0 | V29: =L12+L13 -> 0 | X29: =VLOOKUP(V29,人物数据!D2:G22,3,FALSE) -> 2.25 | Z29: =VLOOKUP(V29,人物数据!D2:G22,4,FALSE) -> 4.5
B30: 额外护甲 | P30: 特殊护甲 | R30: 无
B31: 额外坚韧 | P31: 坚韧加值 | R31: =L13 -> 0 | T31: 武器训练
B32: 最终数值 | E32: =+E29+E30+E31+R31 -> 0 | G32: =+G29+G30+G31+R31 -> 0 | I32: =+I29+I30+I31+R31 -> 0 | K32: =+K29+K30+K31+R31 -> 0 | M32: =+M29+M30+M31+R31 -> 0 | O32: =+O29+O30+O31+R31 -> 0 | T32: 基础 | V32: 例如：基本武器训练（原始）
T33: 格斗
B34: 防护立场（简） | T34: 手枪
B35: 名称 | E35: 防护类型 | G35: 减伤数值 | I35: 完全失效 | L35: 过载 | O35: 持续时间/充能 | T35: 重型
T36: 异种/特种 | AF36: =SUM(AF12:AG35) -> 0 | AL36: =SUM(AL12:AM35) -> 0 | AP36: =SUM(AP12:AQ35) -> 0
T37: 其他
AD38: 最好使用excel或wps打开本卡
T39: 影响力天赋
B40: 基础技能 | T40: 平等待遇 | V40: 例如：平等待遇（国教） | AD40: 使用ALT+ENTER换行
...

Sheet 武备
B2: 近 战 武 器 | AD2: 武器改装/升级效果
B3: 名称 | F3: 类型 | H3: 射程 | J3: 伤害 | L3: 破甲 | N3: 特性 | S3: 重量 | T3: 花费 | U3: 品质 | W3: 改装/升级 | AB3: 花费 | AD3: 改装名称 | AH3: 效果描述
AH4: =_xlfn.IFNA(IF(AD4=0,"",VLOOKUP(AD4,附表!$AJ$65:$AK$73,2,FALSE)),"")
AH6: =_xlfn.IFNA(IF(AD6=0,"",VLOOKUP(AD6,附表!$AJ$65:$AK$73,2,FALSE)),"")
B8: 远程武器 | AH8: =_xlfn.IFNA(IF(AD8=0,"",VLOOKUP(AD8,附表!$AJ$65:$AK$73,2,FALSE)),"")
B9: 名称 | F9: 类型 | H9: 射程 | J9: 射速 | L9: 伤害 | N9: 破甲 | O9: 弹容 | Q9: 装填 | S9: 特性 | Y9: 品质 | AA9: 重量 | AB9: 花费
AH10: =_xlfn.IFNA(IF(AD10=0,"",VLOOKUP(AD10,附表!$AJ$65:$AK$73,2,FALSE)),"")
F11: 弹药 | O11: 弹夹 | S11: 改装
O12: 5 | AH12: =_xlfn.IFNA(IF(AD12=0,"",VLOOKUP(AD12,附表!$AJ$65:$AK$73,2,FALSE)),"")
F13: 弹药 | O13: 弹夹 | S13: 改装
O14: 6 | AH14: =_xlfn.IFNA(IF(AD14=0,"",VLOOKUP(AD14,附表!$AJ$65:$AK$73,2,FALSE)),"")
F15: 弹药 | O15: 弹夹 | S15: 改装
O16: 40 | AH16: =_xlfn.IFNA(IF(AD16=0,"",VLOOKUP(AD16,附表!$AJ$65:$AK$73,2,FALSE)),"")
F17: 弹药 | O17: 弹夹 | S17: 改装
B18: 弹药和榴弹等
B19: 名称 | F19: 类型/数量 | H19: 伤害 | J19: 破甲 | L19: 特性/适配/描述 | X19: 基重 | Y19: 单费 | Z19: 数量 | AA19: 重量 | AB19: 花费 | AD19: 购买物品资金自填减费配平/已并入已用经费
AA20: =IFERROR(IF(OR(ISBLANK(X20),ISBLANK(Z20),X20=0,Z20=0),"",X20*Z20),"") | AB20: =IF(OR(Y20=0,ISNUMBER(Z20)=FALSE,Z20=""),"",IFERROR(Y20*Z20,"")) | AD20: 多个相同物品减费配平 | AK20: 单个物品配平
AA21: =IFERROR(IF(OR(ISBLANK(X21),ISBLANK(Z21),X21=0,Z21=0),"",X21*Z21),"") | AB21: =IF(OR(Y21=0,ISNUMBER(Z21)=FALSE,Z21=""),"",IFERROR(Y21*Z21,"")) | AD21: 名称 | AH21: 单减费 | AI21: 数量 | AJ21: 总减费 | AK21: 名称 | AO21: 减费数
AA22: =IFERROR(IF(OR(ISBLANK(X22),ISBLANK(Z22),X22=0,Z22=0),"",X22*Z22),"") | AB22: =IF(OR(Y22=0,ISNUMBER(Z22)=FALSE,Z22=""),"",IFERROR(Y22*Z22,"")) | AJ22: =IFERROR(IF(OR(ISBLANK(AH22),ISBLANK(AI22),AH22=0,AI22=0),"",AH22*AI22),"")
AA23: =IFERROR(IF(OR(ISBLANK(X23),ISBLANK(Z23),X23=0,Z23=0),"",X23*Z23),"") | AB23: =IF(OR(Y23=0,ISNUMBER(Z23)=FALSE,Z23=""),"",IFERROR(Y23*Z23,"")) | AJ23: =IFERROR(IF(OR(ISBLANK(AH23),ISBLANK(AI23),AH23=0,AI23=0),"",AH23*AI23),"")
AA24: =IFERROR(IF(OR(ISBLANK(X24),ISBLANK(Z24),X24=0,Z24=0),"",X24*Z24),"") | AB24: =IF(OR(Y24=0,ISNUMBER(Z24)=FALSE,Z24=""),"",IFERROR(Y24*Z24,"")) | AJ24: =IFERROR(IF(OR(ISBLANK(AH24),ISBLANK(AI24),AH24=0,AI24=0),"",AH24*AI24),"")
AA25: =IFERROR(IF(OR(ISBLANK(X25),ISBLANK(Z25),X25=0,Z25=0),"",X25*Z25),"") | AB25: =IF(OR(Y25=0,ISNUMBER(Z25)=FALSE,Z25=""),"",IFERROR(Y25*Z25,"")) | AJ25: =IFERROR(IF(OR(ISBLANK(AH25),ISBLANK(AI25),AH25=0,AI25=0),"",AH25*AI25),"")
B26: 防护立场&饰品&其他 | AJ26: =IFERROR(IF(OR(ISBLANK(AH26),ISBLANK(AI26),AH26=0,AI26=0),"",AH26*AI26),"")
B27: 名称 | F27: 效果描述 | AA27: 重量 | AB27: 花费 | AJ27: =IFERROR(IF(OR(ISBLANK(AH27),ISBLANK(AI27),AH27=0,AI27=0),"",AH27*AI27),"")
AJ28: =IFERROR(IF(OR(ISBLANK(AH28),ISBLANK(AI28),AH28=0,AI28=0),"",AH28*AI28),"")
AJ29: =IFERROR(IF(OR(ISBLANK(AH29),ISBLANK(AI29),AH29=0,AI29=0),"",AH29*AI29),"")
AJ30: =IFERROR(IF(OR(ISBLANK(AH30),ISBLANK(AI30),AH30=0,AI30=0),"",AH30*AI30),"")
AJ31: =IFERROR(IF(OR(ISBLANK(AH31),ISBLANK(AI31),AH31=0,AI31=0),"",AH31*AI31),"")
AJ32: =IFERROR(IF(OR(ISBLANK(AH32),ISBLANK(AI32),AH32=0,AI32=0),"",AH32*AI32),"")
B33: 护甲 | AJ33: =IFERROR(IF(OR(ISBLANK(AH33),ISBLANK(AI33),AH33=0,AI33=0),"",AH33*AI33),"")
B34: 名称 | F34: 防护部位 | H34: AP | J34: 效果描述 | AA34: 重量 | AB34: 花费 | AJ34: =IFERROR(IF(OR(ISBLANK(AH34),ISBLANK(AI34),AH34=0,AI34=0),"",AH34*AI34),"")
AJ35: =IFERROR(IF(OR(ISBLANK(AH35),ISBLANK(AI35),AH35=0,AI35=0),"",AH35*AI35),"")
AJ36: =IFERROR(IF(OR(ISBLANK(AH36),ISBLANK(AI36),AH36=0,AI36=0),"",AH36*AI36),"")
AJ37: =IFERROR(IF(OR(ISBLANK(AH37),ISBLANK(AI37),AH37=0,AI37=0),"",AH37*AI37),"")
AJ38: =IFERROR(IF(OR(ISBLANK(AH38),ISBLANK(AI38),AH38=0,AI38=0),"",AH38*AI38),"")
AJ39: =IFERROR(IF(OR(ISBLANK(AH39),ISBLANK(AI39),AH39=0,AI39=0),"",AH39*AI39),"")
AJ40: =IFERROR(IF(OR(ISBLANK(AH40),ISBLANK(AI40),AH40=0,AI40=0),"",AH40*AI40),"")
B41: 物品 | AJ41: =IFERROR(IF(OR(ISBLANK(AH41),ISBLANK(AI41),AH41=0,AI41=0),"",AH41*AI41),"")
B42: 名称 | F42: 具体 | X42: 基重 | Y42: 单费 | Z42: 数量 | AA42: 重量 | AB42: 花费 | AJ42: =IFERROR(IF(OR(ISBLANK(AH42),ISBLANK(AI42),AH42=0,AI42=0),"",AH42*AI42),"")
B43: 背 包 | AA43: =IFERROR(IF(OR(ISBLANK(X43),ISBLANK(Z43),X43=0,Z43=0),"",X43*Z43),"") | AB43: =IF(OR(Y43=0,ISNUMBER(Z43)=FALSE,Z43=""),"",IFERROR(Y43*Z43,"")) | AJ43: =IFERROR(IF(OR(ISBLANK(AH43),ISBLANK(AI43),AH43=0,AI43=0),"",AH43*AI43),"")
...

Sheet 数据导入
B2: 人物导入，但是作者只用过海豹，别的骰娘行不行暂时不知道！ | O2: 表格制作者们 | S2: 1.3 | X2: 1.6
B3: 右键下格，点击“复制”，并在下方的TXT栏“粘贴”就可以导出文本，然后再选中文本，复制到最上方显示框，然后再剪切进QQ可以避免黏贴的是图片的问题。 也可以直接复制下格，复制进一个TXT文本。 | O3: （排名不分前后） | S3: 武器自动化！ | X3: 完善自动化，添加了改装描述简要查找，购买资金配平功能，并更改了武器的自动化逻辑。
O4: 勒
O5: 迮越
B6: =人物!AC1 -> .st格斗0射击0力量0坚韧0敏捷0智力0感知0意志0交际0生命值生命值上限0命运点命运点上限威胁0恐吓0攀爬0运动0游泳0酗酒0狂欢0躲藏0闪避0潜行0估价0逻辑0赌博0警觉0搜查0搜索0察言观色0交易0欺诈0搜集信息0伪装0吸引0扯淡0指挥0 | O6: 晨星
O7: 一壶
O8: 五三点九
O9: IAN
O10: 浣熊旅記
S11: 1.31 | X11: 1.61
S12: 添加了更多弹药并并入自动化中。 优化了1.3版本更新后，弹药计算总数时只填充数量会导致总数显示错误的bug | X12: 修复一些bug并优化
X20: 1.62
S21: 1.4 | X21: 修复一些bug并优化，完善自动化并更改了天赋与物品的自动化逻辑。
S22: 添加了机机风味美化，修复了角色卡没有纯洁印记的漏洞 | U22: 增加了天赋及技能详情速查表，购物表并加入了自动化，添加住宿和医疗表，以及添加了机械神甫晋升表。
X29: 1.63
X30: 更新了资金方面，更新了自动计算目前等级，更改了武器的自动化逻辑，添加了一些标注，新增内置了车卡战斗指南 小幅调整了‘人物’中的排版，增加了每个部位自动计算护甲+坚韧加值得出每个部位最终都有多少甲的功能，邀请了没被邀请的修女的钱包
S31: 1.5 | U31: 分版：半自动
S32: 优化并微调了排版，完善了并新增了更多自动化，对齐了半自动灵能最新版本，新增了可以自己填入非自动化内的内容并入自动化的功能，修复了一些bug | U32: 浣熊旅記接手并制作了半自动姐妹卡，重构优化了灵能相关，并制作了新版美化
X38: 1.64
X39: 同步更新了一些老旧翻译问题，自动化添加了有关背景包的自动功能。

Sheet 灵能
B2: 持有情况 | K2: 灵能相关速查 | Q2: 施法聚焦
B3: 类别 | C3: 次级 | D3: 生化 | E3: 预言 | F3: 操火 | G3: 遥感 | H3: 传心 | I3: 巫术 | J3: 其他 | K3: 优异灵能 | M3: 灵能等级 | O3: 房规加成 | Q3: DH施法
B4: 数量 | Q4: 束缚 | R4: 自由 | S4: 引导
B5: 精通 | K5: 专注/法器 | M5: 灵能感应 | O5: WP | P5: WB | Q5: =ROUND(R5/2,0) -> 0 | R5: =M4 -> 0 | S5: =R5+3 -> 3
B6: 专攻 | O6: =人物!K17 -> 0 | P6: =人物!L17 -> 0 | Q6: RT施法
B7: 额外 | K7: 其他天赋 | Q7: 束缚 | R7: 自由 | S7: 引导
B8: 共计 | C8: =IF(M4="","",IF(C6="√",2,0)+P6+K4+C7) | D8: =IF(M4="","",IF(D6="√",2,0)+P6+K4+D7) | E8: =IF(M4="","",IF(E6="√",2,0)+P6+K4+E7) | F8: =IF(M4="","",IF(F6="√",2,0)+P6+K4+F7) | G8: =IF(M4="","",IF(G6="√",2,0)+P6+K4+G7) | H8: =IF(M4="","",IF(H6="√",2,0)+P6+K4+H7) | I8: =IF(M4="","",IF(I6="√",2,0)+P6+K4+I7) | J8: =IF(M4="","",IF(J6="√",2,0)+P6+K4+J7) | Q8: =Q5*5+O6 -> 0 | R8: =R5*5+O6 -> 0 | S8: =S5*5+O6 -> 15
B10: ↓搜索框
B11: 灵能类别 | H11: 灵能名称 | N11: 加值 | P11: 束缚 | Q11: {=IF(M4="","",Q5&"D10+"&_xlfn.SWITCH(E11,"次级灵能",C8,"生化学科",D8,"预言学科",E8,"操火学科",F8,"遥感学科",G8,"传心学科",H8,"高阶秘仪",I8,"其他灵能",J8,P6+K4))}
P12: 自由 | Q12: {=IF(M4="","",R5&"D10+"&_xlfn.SWITCH(E11,"次级灵能",C8,"生化学科",D8,"预言学科",E8,"操火学科",F8,"遥感学科",G8,"传心学科",H8,"高阶秘仪",I8,"其他灵能",J8,P6+K4))}
P13: 引导 | Q13: {=IF(M4="","",S5&"D10+"&_xlfn.SWITCH(E11,"次级灵能",C8,"生化学科",D8,"预言学科",E8,"操火学科",F8,"遥感学科",G8,"传心学科",H8,"高阶秘仪",I8,"其他灵能",J8,P6+K4))}
B14: Ps：可以在灵能大全表最末自己手动添加房规灵能，会自动同步
B15: 灵 能 详 情
B16: 灵能名称 | E16: 灵能类别 | H16: 阈值 | K16: 聚焦 | N16: 维持 | Q16: 范围
B17: =IFERROR(VLOOKUP(K11,灵能表[],1,0),"") | E17: =IFERROR(VLOOKUP(K11,灵能表[],2,0),"") | H17: =IFERROR(VLOOKUP(K11,灵能表[],3,0),"") | K17: =IFERROR(VLOOKUP(K11,灵能表[],4,0),"") | N17: =IFERROR(VLOOKUP(K11,灵能表[],5,0),"") | Q17: =IFERROR(VLOOKUP(K11,灵能表[],6,0),"")
B18: =IFERROR(VLOOKUP(K11,灵能表[],7,0),"")
B30: 超量释放 | E30: =IFERROR(VLOOKUP(K11,灵能表[],8,0),"")
B35: 次 级 灵 能
B36: 次级灵能
B43: 次级秘仪
B46: 学 科 灵 能
B57: 其 他 灵 能

Sheet 灵能大全
B2: 灵能名称 | C2: 灵能类别 | D2: 阈值 | E2: 聚焦 | F2: 维持 | G2: 范围 | H2: 能力 | I2: 超量释放
B3: 鼓舞氛围 | C3: 次级灵能 | D3: 6 | E3: 完整动作 | F3: 可 | G3: 自身 | H3: 这是个好的灵能，它让你看上去很好，所有看到你的人都会忍不住想对你说好话，这很好。另外，看到你的人会觉得充满自信，以至于对抗恐惧和压制的检定 +20。 | I3: /
B4: 减缓痛苦 | C4: 次级灵能 | D4: 8 | E4: 部分动作 | F4: 否 | G4: 10m | H4: 范围内你指定的一个生物（也可以是你自己）移除 1 级虚弱。 | I4: 每超过阀值 5 点，额外移除 1 级虚弱。
B5: 痉挛 | C5: 次级灵能 | D5: 7 | E5: 部分动作 | F5: 否 | G5: 50m | H5: 你可以瞬间使目标肌肉痉挛。目标可以进行意志检定抵抗此效果，失败会全身发痒，陷入一阵无法控制的痉挛，并立刻倒地。如果目标持有射击武器，该武器会走火，目标正常进行 BS 检定并击中最接近的人。 | I5: 每超过阀值 5 点，你可以多指定一个目标，或者将意志检定难度提高一级。
B6: 武器故障 | C6: 次级灵能 | D6: 8 | E6: 完整动作 | F6: 否 | G6: 50m | H6: 用你的意志干扰机魂，范围内你指定的一件不具有原始特性的武器自动发生故障。武器故障可以通过正常方法排除。注意机械神教对这种做法很反感，对这种灵能者往往持不信任态度。 | I6: 每超过阀值 5 点，影响范围增加10m，或者多指定一件武器。
B7: 医疗者 | C7: 次级灵能 | D7: 7 | E7: 完整动作 | F7: 否 | G7: 10m | H7: 该灵能只能作用于范围内的一个自愿目标（包括你自己），并使其恢复 1d5 点伤害（优先恢复致命伤害）。但是反复使用这种治疗手段存在危险，人体会开始抵制亚空间的能量。如果目标在六小时之内再次被施以此灵能，他必须进行坚韧检定，否则会受到而不是恢复1d5 伤害，该伤害无视坚韧加值和护甲防护。 | I7: /
B8: 把戏 | C8: 次级灵能 | D8: 5 | E8: 部分动作 | F8: 可 | G8: 自身 | H8: 你巧妙地影响身边的“场”，让自己在游戏中作弊的技巧更为高超。灵能生效期间，赌博技能将变为你的基本技能，且得到二级精通（+20）。如果你已经掌握了赌博技能，则该技能检定 +20。但如果你在赌博技能上已经有任何一级精通，该灵能无效，因为你已经达到这个水准了。 | I8: /
B9: 白噪音 | C9: 次级灵能 | D9: 8 | E9: 完整动作 | F9: 可 | G9: 10m | H9: 让区域内充满亚空间干扰，使区域内的任何目标都难以被侦测。尝试用灵能手段或技术手段对该区域内任何目标进行侦测的检定变为艰难(-20)。如果侦测手段不需要检定，那么侦测者需要进行一个常规(+10)意志检定(使用灵能手段)或常规(+10)智力检定(使用科技手段)。 | I9: 每超过阀值 5 点，影响范围增加10m。
B10: 爆炸闪光 | C10: 次级灵能 | D10: 6 | E10: 部分动作 | F10: 否 | G10: 20m | H10: 你制造出一阵闪光爆炸，范围内的任何人都要进行一次常规（+20）意志检定，失败则眩晕 1 轮。 | I10: 每超过阀值 10 点，检定难度提升一级。
B11: 变色龙 | C11: 次级灵能 | D11: 7 | E11: 部分动作 | F11: 可 | G11: 自身 | H11: 让自己身体颜色与环境一致。躲藏+30，针对你的射击 BS-20。 | I11: /
B12: 抵抗附身 | C12: 次级灵能 | D12: 6 | E12: 反射动作 | F12: 否 | G12: 自身 | H12: 建立精神守护保卫自己的意志。接下来的一小时之内，抵抗恶魔的附身时，你可以重投任何失败的意志检定。 | I12: /
B13: 凋零 | C13: 次级灵能 | D13: 6 | E13: 完整动作 | F13: 否 | G13: 3d10m | H13: 你引发一阵恶毒的波动席卷四周，使范围内的所有“正常”植物凋零死亡。 | I13: 每超过阀值 5 点，影响范围增加1d10m。
B14: 非凡精准 | C14: 次级灵能 | D14: 8 | E14: 部分动作 | F14: 否 | G14: 自身 | H14: 用亚空间的力量引导自己瞄准。到你的下一回合结束，你所做的任何 BS 检定 +30。 | I14: /
... B112: 恶魔咒阵 | C112: 高阶秘仪 | D112: 23 | E112: 完整动作 | F112: 否 | G112: 50m | H112: 通过编织亚空间能量的术式，巫师可以尝试驱退、困缚并夺取对恶魔实体的控制权。 施展成功后，巫师可与目标恶魔生物进行意志对抗检定，以此对其施加厄咒。或者，如果目标恶魔的意志属性为 50 或更低，则巫师可改为强制进行一次恶魔掌控检定来支配它。 特殊：这项能力仅能影响同时具有恶魔特性和亚空间不稳定特性的实体。 | I112: 每超过阈值 5 点，巫师在意志对抗和恶魔掌控检定上便获得 +10 加值。
B113: 恶毒诅咒 | C113: 高阶秘仪 | D113: 特殊 | E113: 完整动作 | F113: 否 | G113: 视线范围内 | H113: 阈值：祸祟 16；致盲 20；催命 23 你祈求扭曲交缠的恶性能量，为受害者带去灾祸与诅咒。此处列出了三种不同的诅咒形式，当然，世上的诅咒形式显然不止于此。无论面对何种诅咒，受害者均可尝试通过一次难度为挑战（+0）的意志检定，以此抵抗诅咒效果。 祸祟 Hex：受害者饱受厄运缠身、蚀骨寒意与超自然的恐惧折磨。在接下来的 1d5 小时内，受害者的所有属性检定与技能检定均承受 -10 减值。若抵抗此能力的检定失败度为 3 及以上，受害者还必须额外在表 8-4：震惊（Shock）上掷骰（见《黑暗异端》第 233 页），此情形被视作亚空间惊吓。 致盲 Blindness：受害者的双眼被白内障填满，泣出血泪，陷入失明状态，持续 1d5 小时。若抵抗此巫术的检定失败度为 3 及以上，受害者的双眼会在血雨飞溅中被摧毁，对头部造成 1d10 R 伤害，并且会永久失明（若其幸存，则需更换假眼）。双眼被摧毁还会带给受害者 1d10 点失心。 催命 Death：通过遏停心跳、引爆血管、撕裂内脏以及其他种种可怖方式，此诅咒的威力足以使人丧失行动能力，甚至致人死亡。受害者遭受 3d10+10 点坚韧伤害（若其具有超自然坚韧（x2）等特性，则伤害减半）。受害者的坚韧降至 0 点时，其立即死亡。若此诅咒的受害者存活下来，则坚韧伤害可如常治疗。 注意：因诅咒而死时，受害者可以燃烧 1 命运点来避免暴毙，并恢复 1d5 坚韧。但受害者会陷入昏迷状态，亟需紧急救治。 特殊：每次施展诅咒时，巫师必须通过一次难度为挑战（+0）的意志检定，否则其获得 1d5 点堕落。 | I113: 每超过阈值 5 点，受害者抵抗诅咒的检定难度便提高一级，最高难度为艰巨（-30）。
B114: 地狱爆破 | C114: 高阶秘仪 | D114: 22 | E114: 部分动作 | F114: 否 | G114: 5m x 意志加值 | H114: 使用此能力时，你可以从亚空间引导能量，向受害者投掷一团纯粹的毁灭性爆流，将其点燃并炸成碎片。如同远程攻击一般，你进行一次远程技巧（BS）检定以命中目标。检定成功时，你的攻击造成 1d10+WB E 伤害。这次伤害视为具备亚空间武器特性，因此可以穿透大多数护甲与防御。 | I114: 每超过阈值 10 点，便额外造成 1d10 点伤害。
B115: 黑暗导能 | C115: 高阶秘仪 | D115: 25 | E115: 完整动作 | F115: 可 | G115: 20 米半径 | H115: 巫师从亚空间中汲取扭曲力量，用以增强和维系范围内的恶魔生物，巩固恶魔在现实世界的存在，并强化其力量。 作用范围内，任何拥有恶魔特性的生物获得再生特性，其先攻 +1，并在抵抗亚空间不稳定时获得 +10 加值。 特殊：巫师需要为引导这些邪恶能量支付代价。维持灵能的每一轮，施术者都必须通过一次难度为困难（-10）的坚韧检定，否则将失去 1 点承伤。 | I115: 每超过阈值 10 点，范围半径增加 10 米。
B116: 恶意风暴 | C116: 高阶秘仪 | D116: 18 | E116: 完整动作 | F116: 可 | G116: 50 米半径 | H116: 巫师借助亚空间中那些经由灵能回响而传播开的恶意、偏执与仇恨，将突如其来的狂怒、恐慌与杀意，灌注进毫无防备之人的心智中去，并由此引发致命后果。这股情绪浪潮足以将一群普通人变成施暴的狂徒，引起大规模的群体癫狂与血腥暴乱。在能力生效期间，身处范围内的所有活物，每轮必须通过一次难度为挑战（+0）的意志检定，否则便会陷入极度危险且充满暴力的狂怒状态。依据其各自的心智状况，他们要么会疯狂攻击任何触手可及的人，要么会因极度恐惧而四散奔逃。如果受害者屈从于这项能力，其所带来的直接影响将持续到维持结束，再加上额外 1d10 轮。 这项能力属于灵能攻击，同时也被视为恐惧效果，因此能够抵抗恐惧的天赋和特性，对这项能力同样有效。 | I116: 每超过阈值 10 点，范围半径翻倍。
B117: 时间扭曲 | C117: 高阶秘仪 | D117: 20 | E117: 完整动作 | F117: 可 | G117: 自身 | H117: 巫师使自己与周围现实及时间的流动略微错相。巫师的身形变得模糊且飘忽不定，其过去与未来各种可能行动的阴影相互重叠，如幽灵般环绕其身周。 能力生效期间，巫师变得极难被击中，任何对其发起的攻击检定承受 -20 减值。此外，如果巫师在 1d10 中掷出奇数结果（即1、3、5、7、9），则任何成功命中将被抵消，除非该次攻击使用灵能、来自受祝（Blessed）或神圣（Holy）武器，或是具备亚空间武器特性。 特殊：如果巫师遭受亚空间危险，则时间反冲将撕裂巫师自身，对其造成 3d10 E 伤害。 | I117: 每超过阈值 5 点，此能力在维持中断后，效果额外持续 1 轮。
B118: 创造门扉 | C118: 高阶秘仪 | D118: 28 | E118: 完整动作 | F118: 否 | G118: 5m | H118: 巫师凭空召唤出一道燃烧的门扉。这道门扉可用于将巫师传送至他脑海中能清晰回忆起的任何地方。巫师的玩家必须告知游戏主持人他希望门扉通向何处；游戏主持人随后会根据巫师上次身处该地的时间、其心智状态、周遭环境及专注程度，设定一个适当的难度等级。巫师随后可迈步穿过门扉，并基于该难度等级进行智力检定。若检定通过，则一切顺利。若未通过，游戏主持人将决定一个合适的替代目的地——通常是一个巫师宁愿避开的地方。 特殊：穿越如此亵渎的门户，会让使用者比安全限度更接近亚空间的恐怖。任何穿过门扉者都必须通过一个难度为艰难（-20）的意志检定。若检定失败，该角色必须在亚空间危险表上掷骰。 10 米–100 米：常规（+20）；101 米–1000 米：普通（+10）；星球内的任意地点：挑战（+ 0）；星系内的任意地点：困难（-10）；次星区内的任意地点：艰难（-20）；星区内的任意地点：艰巨（-30） | I118: /
B119: 疫病 | C119: 高阶秘仪 | D119: 20 | E119: 部分动作 | F119: 否 | G119: 5m | H119: 巫师轻蔑地一挥手，便将一场瘟疫降于目标身上。目标开始呕出胆汁与鲜血，皮肤上隆起脓包。此疫病持续轮数等于 1d10 减去目标的坚韧加值。目标在染疫期间，全部属性每轮降低 10 点。若其坚韧降低至零，则目标死亡。 超量释放：每超过阈值 5 点，疫病的持续时间增加 1 轮。 特殊：若一名角色死于疫病，其灵魂将归于瘟疫之主纳垢。倒下的尸体会进一步腐烂，并在 5 轮后作为一只瘟疫使者（Plaguebearer）站起（见《黑暗异端》规则书第 354 页）。瘟疫使者会立即攻击附近的任何生物。 | I119: /
B120: 失血术 | C120: 高阶秘仪 | D120: 18 | E120: 部分动作 | F120: 否 | G120: 10m | H120: 巫师朝目标打个响指并吼出一段咒文，使目标的血液沸腾、涌出体外。巫师用意志与目标的坚韧对抗。若对抗成功，目标承受等同于巫师意志加值两倍的伤害（坚韧加值与护甲无法减免此伤害），并会陷入失血状态（见《黑暗异端》规则书第 211 页）。 | I120: /
B121: 颅骨连枷 | C121: 高阶秘仪 | D121: 14 | E121: 部分动作 | F121: 可 | G121: 自身 | H121: 巫师以亚空间为索，将亡者的颅骨束缚在一起，打造出一把燃烧着恶意的颅骨连枷。颅骨连枷显现后，其数据与普通连枷相同（见《黑暗异端》规则书第 139 页），但具有亚空间武器特性，能够绕过大多数护甲与防御。任何受到颅骨连枷伤害的目标将获得 1d10 点失心，并且从第二颗颅骨之后算起，每多使用一颗颅骨打造此连枷，便额外造成 1 点失心。 特殊：显然，使用此能力需要巫师拥有至少一颗颅骨。 | I121: /
B122: 燃烧之语 | C122: 高阶秘仪 | D122: 18 | E122: 部分动作 | F122: 否 | G122: 自身 | H122: 巫师张开嘴巴，将其作为亚空间烈焰的门户。此能力造成 1d10+4 E 伤害，并具有 3 点破甲。其效果范围可延伸至 20 米，并具有火焰特性。此外，由于这些火焰的超自然本质，任何被此能力效果影响的目标都会自动着火（on fire）（见《黑暗异端》规则书第 210 页）。 特殊：在此能力施展期间，巫师无法进行口头交流；这可能会阻止巫师施放某些其他能力。 | I122: /
B123: 免疫冲击 | C123: 高阶秘仪 | D123: 24 | E123: 部分动作 | F123: 否 | G123: 自身 | H123: 巫师吞下一颗实弹弹药，以此强化自身躯体，抵御投射物与粗制武器的攻击。巫师必须通过一次坚韧检定。若检定成功，巫师在 1d5 轮内免疫任何冲击伤害（Impact Type Damage）。 | I123: /
B124: 汲食生命 | C124: 高阶秘仪 | D124: 21 | E124: 完整动作 | F124: 否 | G124: 接触 | H124: 巫师将手指插入目标的血肉，吸收其生命力，直至目标仅剩一具干枯的躯壳。这一能力仅能作用于处在眩晕状态或其他无力反抗的目标。每超过阈值 5 点，巫师便恢复 1 点承伤，同时目标的承伤减少 1 点。巫师恢复的承伤数不能超过其原本的承伤上限。如果目标的承伤降低至零，则目标死亡。 | I124: /
B125: 活体武器 | C125: 高阶秘仪 | D125: 24 | E125: 完整动作 | F125: 可 | G125: 自身 | H125: 巫师将混沌的邪秽符号刻入自己的血肉之中，呼唤亚空间重塑其肉身以应对战斗。在能力生效期间，巫师的属性获得以下提升：近战技巧 +20、力量 +20、坚韧 +10、敏捷 +10。此外，巫师在所有先攻检定中获得 +3 加值，获得天生武器特性，且其所有近战攻击均获得撕裂特性。在此等兽性状态下，他的交际降低 10 点。 | I125: /
... B135: 苦痛浩劫 | C135: 其他灵能 | D135: 28 | E135: 完整动作 | F135: 可 | G135: 以苦痛之拥为中心，10 米半径内 | H135: 苦痛之拥（见第 131 页）的受害者每时每刻承受着难以想象的剧痛与绝望。他们在生与死间遭受不死的折磨，一边是恶魔对其灵魂的啃噬，一边是肉体永无止境的消亡。经由亚空间的回响与放大，苦痛之拥的受害者能将这种难耐的折磨施加于他人，产生粉碎性的效果。他们能撕裂其周围的现实，将实体物质、血肉与心智一并击溃。 爆炸范围内的一切事物都将承受 2d10 R 伤害。该伤害无视除力场防护或护符（Field effects or wards）之外的任何护甲，且受创者将被巨大的力量向后击飞（与凶猛投掷灵能等效）。任何在此攻击下幸存的生物都必须通过一次难度为艰难（-20）的恐惧检定，否则将遭受亚空间惊吓。 | I135: 每超过阈值 10 点，范围半径增加 10 米。

Sheet 武器与防具与弹药
A1: 武器表 | O1: 武器类型 | U1: 武器特性注释 | AH1: 防具表 | AP1: 防具类型
A4: 近 战 武 器 | K4: 格斗武器 †代表该武器需要双手使用 | O4: 格斗 | P4: 格斗武器包括了近战使用的武器， 当你使用这些武器时，在伤害检定上加上你的力量调整值 | U4: 原始 | V4: 原始且基础的设计，这种类型的武器，虽然依然致命，但对更高水平的护甲意义不大。 护甲的所有防护值在对抗原始武器时会加倍，除非护甲也具有原始属性。 | AA4: 充能 | AB4: 因为武器的弹药由不稳定物质构成，或是射击方式所限，这种武器在两次射击间需要时间进行充能。 具有充能特性的武器在开火之后必须花费一轮对武器进行充电并且无法再次使用，实际上你使用这种武器的时候只能隔一轮开火一次。 | AH4: 护甲 | AP4: 原始 | AQ4: 主要使用原始材料制做，例如兽皮和软金属，相较于抵挡子弹，这种护甲更擅长偏折锋刃。 具有原始特性的护甲在对抗不具有原始特性的武器时，只能计算一半的护甲防护（向上取整）。武器破甲在护甲防护取半之后计算。
B5: 名称 | C5: 类型 | D5: 射程 | E5: 伤害 | F5: 破甲 | G5: 特性 | H5: 重量 | I5: 花费 | J5: 原始 | AI5: 名称 | AJ5: 特性 | AK5: AP | AL5: 重量 | AM5: 花费 | AN5: 原始
B6: 斧 | C6: 格斗 | D6: — | E6: 1d10+1 R | F6: 0 | G6: 原始，失衡 | H6: 4 | I6: 20 | AI6: 皮夹克 | AJ6: 手臂 躯干 腿 | AK6: 1 | AL6: 5 | AM6: 25
B7: 黄铜指虎 | C7: 格斗 | D7: — | E7: 1d5−1 I | F7: 0 | G7: 原始 | H7: 0.5 | I7: 5 | AI7: 重皮甲 | AJ7: 手臂 躯干 腿 | AK7: 2 | AL7: 7 | AM7: 100
B8: 棍棒 | C8: 格斗 | D8: — | E8: 1d10 I | F8: 0 | G8: 原始 | H8: 2 | I8: 5 | AI8: 棉布背心 | AJ8: 躯干 | AK8: 2 | AL8: 2 | AM8: 10
B9: 链枷 | C9: 格斗† | D9: — | E9: 1d10+2 I | F9: 0 | G9: 原始，柔韧 | H9: 4 | I9: 20 | AI9: 戈洛兽革甲 | AJ9: 手臂 躯干 腿 | AK9: 3 | AL9: 14 | AM9: 60
B10: 加重武器 | C10: 格斗† | D10: — | E10: 2d10 R | F10: 2 | G10: 原始，笨重 | H10: 7 | I10: 70 | K10: 掷弹筒武器 †代表该武器的伤害，破甲，及特性取决于它们发射的榴弹种类 | O10: 投掷 | P10: 投掷武器包括了所有依靠臂力投掷的武器，像飞刀，斧子，短矛等等 除非它们同时具有格斗武器类型，否则不能进行近战（或者在近战中被视为临时武器） 使用投掷武器时，在伤害检定上加上你的力量调整值（手榴弹类武器例外） | U10: 失衡 | V10: 由于沉重并且在攻击后难以控制，这种类型武器在进行格档的时候会受到 −10 惩罚。 | AA10: 过热 | AB10: 某些武器容易过热，这可能是因为设计的问题或者使用了不稳定的能量供应。 当命中检定投出了 91 以上，表示武器过热。然后投1d10 然后对照“武器过热”表查询结果。 | AI10: 链甲外套 | AJ10: 躯干 | AK10: 3 | AL10: 18 | AM10: 50 | AP10: 防弹 | AQ10: 通过使用包含了能够分散和吸收冲击能量的填充物材料，防弹护甲能有效对抗轻武器，榴散弹，冲击波。 在对抗具有爆炸特性的武器时，只要穿戴者不是正好位于爆炸中心，防弹护甲视为具有 5 点 AP。
B11: 战锤 | C11: 格斗 | D11: — | E11: 1d10+1 I | F11: 0 | G11: 原始，失衡 | H11: 4 | I11: 10 | AI11: 封建铠甲 | AJ11: 全身 | AK11: 5 | AL11: 30 | AM11: 120
B12: 临时武器 | C12: 格斗 | D12: — | E12: d10−2 I | F12: 0 | G12: 原始，失衡 | H12: — | I12: — | AI12: 异形兽皮 | AJ12: 躯干 | AK12: 6 | AL12: 22 | AM12: 5000
B13: 刀 | C13: 格斗 投掷 | D13: 3m | E13: 1d5 R | F13: 0 | G13: 原始 | H13: 0.5 | I13: 5 | AI13: 防弹头盔 | AJ13: 头部 | AK13: 2 | AL13: 2 | AM13: 25 | AN13: 防弹
B14: 飞刀或手里剑 | C14: 投掷 | D14: 5m | E14: 1d5 R | F14: 0 | G14: 原始 | H14: 0.5 | I14: 5 | AI14: 防弹护臂 | AJ14: 手臂 | AK14: 2 | AL14: 1 | AM14: 50
B15: 盾 | C15: 格斗 | D15: — | E15: 1d5 I | F15: 0 | G15: 原始，防御 | H15: 3 | I15: 25 | AI15: 轻型防弹外套 | AJ15: 手臂 躯干 腿 | AK15: 2 | AL15: 4 | AM15: 80
B16: 矛 | C16: 格斗，投掷† | D16: 10m | E16: 1d10 R | F16: 0 | G16: 原始 | H16: 3 | I16: 15 | K16: 霰弹类 | O16: 手枪 | P16: 手枪是可以单手开火的武器，并且可以在近战中使用 无论如何，使用者都不会在近战中因为瞄准器具或者距离受到奖励或者惩罚。 有散射属性的手枪在近战中射击视为近距离平射（但不会有通常近距离平射提供的 +30 加值） | U16: 柔韧 | V16: 一些武器由大量松散的链接单元组成，像是锁环，兽皮等，比如鞭子。因为这类武器攻击时的灵活柔软，使它无法被格档。 | AA16: 捕捉 | AB16: 拥有这种特性的武器被设计用以捕捉目标。 通过一次成功的命中，目标必须通过敏捷检定否则被困住。一个被困住的目标除了尝试结束束缚状态外不能有其他动作。在他的行动轮，他可以尝试挣脱（进行力量检定）或是脱逃（进行敏捷检定）。除非成功脱出，否则目标被视为无助。 | AI16: 防弹背心 | AJ16: 躯干 | AK16: 3 | AL16: 5 | AM16: 50 | AP16: 甲壳 | AQ16: 甲壳护甲将多层特制塑钢纤维，陶瓷甲片，以及其他耐用材料复合制造。 它穿起来很重并且无法很好的保护例如关节之类的护甲接缝处，但是综合防护效果远比那些更轻型的护甲来的优秀。
B17: 剑 | C17: 格斗 | D17: — | E17: 1d10 R | F17: 0 | G17: 原始，平衡 | H17: 3 | I17: 15 | AI17: 防弹夹克 | AJ17: 手臂 躯干 腿 | AK17: 3 | AL17: 6 | AM17: 100
B18: 杖 | C18: 格斗† | D18: — | E18: 1d10 I | F18: 0 | G18: 原始，平衡 | H18: 3 | I18: 10 | K18: 武器伤害类型 E=能量、I=冲击 X=爆炸、R=劈刺 | AI18: 防弹斗篷 | AJ18: 全身 | AK18: 3 | AL18: 8 | AM18: 80
B19: 链锯剑 | C19: 格斗 | D19: — | E19: 1d10+2 R | F19: 2 | G19: 平衡，撕裂 | H19: 6 | I19: 275 | J19: 链锯 | AI19: 卫队防弹甲 | AJ19: 全身 | AK19: 4 | AL19: 11 | AM19: 300
B20: 链锯斧 | C20: 格斗 | D20: — | E20: 1d10+4 R | F20: 2 | G20: 撕裂 | H20: 13 | I20: 450 | AI20: 甲壳头盔 | AJ20: 头部 | AK20: 4 | AL20: 2 | AM20: 250 | AN20: 甲壳
B21: 能量刃 | C21: 格斗 | D21: — | E21: 1d10+3 E | F21: 6 | G21: 能量 | H21: 1.5 | I21: 1750 | J21: 能量 | AI21: 甲壳臂铠 | AJ21: 手臂 | AK21: 5 | AL21: 2 | AM21: 300
B22: 能量剑 | C22: 格斗 | D22: — | E22: 1d10+5 E | F22: 6 | G22: 能量，平衡 | H22: 3.5 | I22: 2500 | O22: 基础 | P22: 基本武器指一般情况下需要双手持 用的武器，但是也能够以 −20 的惩 罚单手持用。 | U22: 笨重 | V22: 庞大并且极端沉重，笨重武器太沉重以至于无法用来防御。此类武器不能用来格档。 | AA22: 粗劣 | AB22: 拥有这个特性武器不是由于糟糕的设计就是因为制作手段所限，不管多么小心的使用，也无法比单纯凭运气使用得到更好的结果。 这样的武器无法通过瞄准得到任何加值。 | AI22: 甲壳胫甲 | AJ22: 腿 | AK22: 5 | AL22: 3 | AM22: 375 | AP22: 纤维 | AQ22: 通过特殊设计和一些加工，纤维护甲是由数千个细胞状个体链接形成。 因为其蜂窝状表层使得它重量更轻，并且在受到外力冲击或高温射线时，护甲表层能够在瞬间硬化，以分散攻击的能量。
B23: 震击槌 | C23: 格斗 | D23: — | E23: 1d10 I | F23: 0 | G23: 震击 | H23: 2.5 | I23: 150 | J23: 震击 | AI23: 执行者轻甲壳护甲 | AJ23: 手臂 躯干 腿 | AK23: 5 | AL23: 15 | AM23: 575
B24: 电击链枷 | C24: 格斗† | D24: — | E24: 1d10+2 I | F24: 0 | G24: 震击，柔韧 | H24: 4.5 | I24: 375 | AI24: 甲壳胸铠 | AJ24: 躯干 | AK24: 6 | AL24: 7 | AM24: 600
B25: 远程武器 | AI25: 风暴突击甲壳护甲 | AJ25: 全身 | AK25: 6 | AL25: 17 | AM25: 3750
B26: 名称 | C26: 类型 | D26: 射程 | E26: 射速 | F26: 伤害 | G26: 破甲 | H26: 弹夹 | I26: 装填 | J26: 特性 | K26: 重量 | L26: 花费 | M26: 激光 | AI26: 纤维罩帽 | AJ26: 头部 | AK26: 3 | AL26: 0.5 | AM26: 100 | AN26: 纤维
B27: 激光手枪 | C27: 手枪 | D27: 30m | E27: S/–/– | F27: 1d10+2 E | G27: 0 | H27: 30 | I27: 完整 | J27: 可靠 | K27: 1.5 | L27: 50 | AI27: 纤维护臂 | AJ27: 手臂 | AK27: 3 | AL27: 0.5 | AM27: 120
B28: 激光卡宾枪 | C28: 基本 | D28: 60m | E28: S/2/– | F28: 1d10+2 E | G28: 0 | H28: 40 | I28: 完整 | J28: 可靠 | K28: 3 | L28: 75 | O28: 重型 | P28: 重型武器指正常情况下需要双手，且必须被用某些手段固定后使用的武器，一般是用两脚或者三脚的支撑架，不过窗沿，沙包（如果是 RPG的话，肩膀也可以）也可以起到同样效果，这样不会有任何惩罚。使用一件重型武器而没有任何妥善固定会受到 −30 的射击惩罚，并且无法使用半自动或者全自动方式射击。 | U28: 防御 | V28: 一件防御武器，比如盾牌，可以用来阻挡对手的攻击，但是作为攻击手段是非常难以使用的。防御武器在进行格档的时候可以获得+15 的加值，但是在攻击的时候会受到 −10的减值。 | AA28: 易损 | AB28: 某些武器相比其他的更容易出现哑火，可能是因为糟糕的维护或是设计问题。 一件易损的武器在每一次进行半自动或是全自动射击时，如果出现 91 及更高，就会发生故障。 | AI28: 异型纤维甲 | AJ28: 手臂 躯干 腿 | AK28: 4 | AL28: 2 | AM28: 375 | AP28: 动力装甲 | AQ28: 这种最为沉重和精密的护甲拥有自带的动力设备以增加使用者的力量。 动力装甲会使穿着者的力量增加 20 并且体型增大一级（举例：一个体型为中型人类在穿着后会变为大型）。轻型动力装甲使穿着者的力量增加 10 并且体型不变。你必须穿着躯干，手臂和腿部装甲才能得到该力量加成。动力装甲需要穿着者随身携带能量源为其正常运作提供持续补给（一般都是做成背包状）。一个标准的非军用能量源在再次充能或替换之前，至多可以维持动力装甲 1d5 小时正常运作。
B29: 激光步枪 | C29: 基本 | D29: 100m | E29: S/3/– | F29: 1d10+3 E | G29: 0 | H29: 60 | I29: 完整 | J29: 可靠 | K29: 4 | L29: 75 | AI29: 纤维背心 | AJ29: 躯干 | AK29: 4 | AL29: 1 | AM29: 150
B30: 激光长枪 | C30: 基本 | D30: 150m | E30: S/–/– | F30: 1d10+3 E | G30: 1 | H30: 40 | I30: 完整 | J30: 可靠，精准 | K30: 4.5 | L30: 100 | AI30: 纤维作战斗篷 | AJ30: 全身 | AK30: 4 | AL30: 1.5 | AM30: 350
B31: 单兵激光炮 | C31: 重型 | D31: 300m | E31: S/–/– | F31: 5d10+10 E | G31: 10 | H31: 5 | I31: 2完整 | J31: — | K31: 55 | L31: 5000 | AI31: 轻型动力装甲 | AJ31: 全身 | AK31: 7 | AL31: 40 | AM31: 8500 | AN31: 动力
B32: 自动手枪 | C32: 手枪 | D32: 30m | E32: S/–/6 | F32: 1d10+2 I | G32: 0 | H32: 18 | I32: 完整 | J32: — | K32: 2.5 | L32: 75 | M32: 实体弹 | AI32: 动力装甲 | AJ32: 全身 | AK32: 8 | AL32: 65 | AM32: 15000
B33: 短管左轮 | C33: 手枪 | D33: 30m | E33: S/–/– | F33: 1d10+3 I | G33: 0 | H33: 6 | I33: 2完整 | J33: 可靠 | K33: 1 | L33: 40
B34: 短管连发枪 | C34: 手枪 | D34: 30m | E34: S/3/– | F34: 1d10+3 I | G34: 0 | H34: 9 | I34: 完整 | J34: — | K34: 1.5 | L34: 50 | O34: 多次命中 | U34: 平衡 | V34: 一些武器，比如刀剑，在手柄和锋刃部分的重量上进行了特别设计，使它更容易被挥动。具有平衡特性的武器用于格挡时，WS 检定获得 +10 加值。 | AA34: 可靠 | AB34: 基于多次试验和值得信赖的技术。可靠特性的武器很少出现问题。 当此类武器故障的时候，投 1d10，只有出现 10 的时候才会确实发生故障，否则只是正常射失而已。
B35: 手铳 | C35: 手枪 | D35: 35m | E35: S/–/– | F35: 1d10+4 I | G35: 2 | H35: 5 | I35: 2完整 | J35: — | K35: 3 | L35: 65
B36: 自动步枪 | C36: 基本 | D36: 90m | E36: S/3/10 | F36: 1d10+3 I | G36: 0 | H36: 30 | I36: 完整 | J36: — | K36: 3.5 | L36: 100 | O36: 原始位置 | P36: 第二 | Q36: 第三 | R36: 第四 | S36: 第五 | T36: 其余命中
B37: 来复猎枪 | C37: 基本 | D37: 150m | E37: S/–/– | F37: 1d10+3 I | G37: 0 | H37: 5 | I37: 完整 | J37: 精准 | K37: 5 | L37: 100
B38: 霰弹猎枪 | C38: 基本 | D38: 30m | E38: S/–/– | F38: 1d10+4 I | G38: 0 | H38: 2 | I38: 2完整 | J38: 可靠，散射 | K38: 5 | L38: 60 | O38: 头部 | P38: 头部 | Q38: 手臂 | R38: 躯干 | S38: 手臂 | T38: 躯干
B39: 泵动霰弹枪 | C39: 基本 | D39: 30m | E39: S/–/– | F39: 1d10+4 I | G39: 0 | H39: 8 | I39: 2完整 | J39: 散射 | K39: 5 | L39: 75
B40: 战斗霰弹枪 | C40: 基本 | D40: 30m | E40: S/3/– | F40: 1d10+4 I | G40: 0 | H40: 18 | I40: 完整 | J40: 散射 | K40: 6.5 | L40: 150 | O40: 手臂 | P40: 手臂 | Q40: 躯干 | R40: 头部 | S40: 躯干 | T40: 手臂 | U40: 撕裂 | V40: 撕裂武器是一种恶毒的，利用大量快速移动的锯齿撕裂血肉的装置。 这些武器在投伤害时投一个额外伤害骰，之后去掉一个点数最小的骰子。 | AA40: 爆炸 | AB40: 许多导弹，榴弹，以及一些枪械在击中目标的时候会引发爆炸。 当具有爆炸特性的武器发射之后，任何位于武器爆炸半径范围内的目标都会受到伤害。需要为每一个受到爆炸影响的人分别投命中位置和伤害。
B41: 重机枪 | C41: 重型 | D41: 120m | E41: –/–/10 | F41: 1d10+4 I | G41: 3 | H41: 200 | I41: 2完整 | J41: — | K41: 35 | L41: 750
B42: 爆矢手枪 | C42: 手枪 | D42: 30m | E42: S/2/– | F42: 1d10+5 X | G42: 4 | H42: 8 | I42: 完整 | J42: 撕裂 | K42: 3.5 | L42: 250 | M42: 爆矢 | O42: 躯干 | P42: 躯干 | Q42: 手臂 | R42: 头部 | S42: 手臂 | T42: 躯干
...

Sheet 详情速查
B2: 物品详细信息查找处 | L2: 技能具体详情速查处 | W2: 名称 | X2: 购买物物品简要信息（购买精简，详细去查找处） | Y2: 重量 | Z2: 花费 | AA2: 稀有度 | AB2: 类型
W3: 背包 | X3: 大口袋背包，承重最多50kg | Y3: 1 | Z3: 10 | AA3: 丰富 | AB3: 服装
B4: 名称 | D4: 详细信息 | L4: 天赋名称 | O4: 详细信息 | W4: 卡梅莱林斗篷 | X4: 躲藏+20，不动时被射击的话视为双倍距离外 | Y4: 0.5 | Z4: 500 | AA4: 稀有 | AB4: 服装
D5: =_xlfn.IFNA(IF(B5=0,"",VLOOKUP(B5,附表!AC2:AH70,2,FALSE)),"") | O5: =_xlfn.IFNA(IF(L5=0,"",VLOOKUP(L5,附表!AQ5:附表!AT52,4,FALSE)),"") | W5: 护身符 | X5: 可以为佩戴者带来帝皇慈悲指引的小饰物 | Y5: — | Z5: 特殊 | AA5: 一般 | AB5: 服装
W6: 计时器 | X6: 手持或手腕上的时间记录装置 | Y6: — | Z6: 40 | AA6: 充裕 | AB6: 服装
B7: 重量 | C7: 花费 | W7: 缆线盒 | X7: 在垂直表面攀爬获+30，检定失败也不会掉落 | Y7: 2 | Z7: 25 | AA7: 普及 | AB7: 服装
B8: =_xlfn.IFNA(IF(B5=0,"",VLOOKUP(B5,附表!AC2:AH70,3,FALSE)),"") | C8: =_xlfn.IFNA(IF(B5=0,"",VLOOKUP(B5,附表!AC2:AH70,4,FALSE)),"") | L8: 描述 | W8: 服装 | X8: 各种各样的服装服饰 | Y8: — | Z8: 特殊 | AA8: 充裕 | AB8: 服装
B9: 稀有度 | L9: =_xlfn.IFNA(IF(L5=0,"",VLOOKUP(L5,附表!AQ5:附表!AT52,2,FALSE)),"") | W9: 爆破项圈 | X9: 爆炸时佩戴者死亡且产生半径3m1d10爆炸伤害 | Y9: 1 | Z9: 55 | AA9: 稀有 | AB9: 服装
B10: =_xlfn.IFNA(IF(B5=0,"",VLOOKUP(B5,附表!AC2:AH70,5,FALSE)),"") | W10: 过滤塞 | X10: 塞鼻孔后对抗毒气的坚韧+20 | Y10: — | Z10: 15 | AA10: 普及 | AB10: 服装
B11: 类型 | W11: 红外目镜 | X11: 温血动物热量可视化，不怕黑暗，夜晚视力+20 | Y11: 0.5 | Z11: 275 | AA11: 稀有 | AB11: 服装
B12: =_xlfn.IFNA(IF(B5=0,"",VLOOKUP(B5,附表!AC2:AH70,6,FALSE)),"") | L12: 属性 | W12: 成像面罩 | X12: 获得黑暗视觉特性，优秀品质免疫闪光弹 | Y12: 0.5 | Z12: 100 | AA12: 匮乏 | AB12: 服装
L13: =_xlfn.IFNA(IF(L5=0,"",VLOOKUP(L5,附表!AQ5:附表!AT52,3,FALSE)),"") | W13: 循环呼吸器 | X13: 免除毒气，水下存活，滤毒罐1h后需完整动作更换（滤毒罐一个25g，重量可忽略） | Y13: 1 | Z13: 50 | AA13: 匮乏 | AB13: 服装
W14: 缓冲手套 | X14: 单手使用基础武器不承受−20的减值 | Y14: 0.5 | Z14: 85 | AA14: 稀有 | AB14: 服装
W15: 防毒面具 | X15: 对抗毒气的坚韧+30，失败可重投 | Y15: 0.5 | Z15: 25 | AA15: 一般 | AB15: 服装
W16: 太空服 | X16: 可对抗有害环境，内置循环呼吸器，可真空存活 | Y16: 8 | Z16: 100 | AA16: 丰富 | AB16: 服装
W17: 生化皮肤 | X17: 无甲时+2甲，潜行躲避+10，红外/黑暗视觉不可见 | Y17: 2 | Z17: 2500 | AA17: 罕见 | AB17: 服装
W18: 占卜盒/扫描仪 | X18: 警觉+20，可使用技术应用扫描肉眼不可见的东西， 会被50cm+ 的墙壁或防护阻挡侦测 | Y18: 0.5 | Z18: 145 | AA18: 匮乏 | AB18: 消耗品
W19: 自动书写笔 | X19: 精准快速的复制文本，生计（抄写员） +10 | Y19: — | Z19: 55 | AA19: 匮乏 | AB19: 药物
W20: 组合工具 | X20: 一套通用工具，技术应用 +10 | Y20: 1 | Z20: 200 | AA20: 稀有 | AB20: 药物
B21: 天赋具体详情速查处 | W21: 数据板 | X21: 被广泛使用，用来记录和读取编辑完成的文本或是其他的音频和视频数据 | Y21: 0.5 | Z21: 25 | AA21: 普及 | AB21: 消耗品
W22: 爆破药 | X22: 造成 3d10 加每公斤 2 点的爆炸伤害，范围每公斤5米。 | Y22: 1 | Z22: 250 | AA22: 匮乏 | AB22: 消耗品
B23: 天赋名称 | D23: 详细信息 | W23: 刑讯工具 | X23: 一套花样百出的刑具，审讯+20 | Y23: 1 | Z23: 375 | AA23: 罕见 | AB23: 消耗品
D24: =_xlfn.IFNA(IF(B24=0,"",VLOOKUP(B24,附表!W3:附表!X126,2,FALSE)),"") | W24: 照明球/发光器 | X24: 照亮 12 米的距离。可以持续工作1d5h | Y24: 0.5 | Z24: 15 | AA24: 充裕 | AB24: 药物
W25: 抓钩 | X25: 钩中目标后，可徒手攀爬或通过绞盘把自己拉上去 | Y25: 2 | Z25: 30 | AA25: 普及 | AB25: 消耗品
W26: 激光切割刀 | X26: 切割，焊枪，每轮可处理 10cm 的金属（根据材质稍有不同） | Y26: 4 | Z26: 65 | AA26: 一般 | AB26: 消耗品
B27: 先决条件 | W27: 多功能望远镜 | X27: 放大观察远距离目标 | Y27: 0.5 | Z27: 55 | AA27: 一般 | AB27: 消耗品
B28: =_xlfn.IFNA(IF(B24=0,"",VLOOKUP(B24,附表!W3:附表!Y126,3,FALSE)),"") | W28: 镣铐 | X28: 一种枷锁，用来禁锢他人 | Y28: 1 | Z28: 35 | AA28: 丰富 | AB28: 消耗品
W29: 微型通讯器 | X29: 短距离通讯，可在一公里之内清晰的传递讯息。 | Y29: — | Z29: 20 | AA29: 一般 | AB29: 药物
W30: 万能钥匙 | X30: 对开锁时的侵入+30 | Y30: — | Z30: 150 | AA30: 匮乏 | AB30: 药物
L31: 生化义肢 | W31: 图像记录仪 | X31: 简易记录装置，可将储存的信息重放 | Y31: 1 | Z31: 100 | AA31: 一般 | AB31: 药物
W32: 灵能法器 | X32: 灵能者使用法器进行专注时，检定 +10 | Y32: — | Z32: 100 | AA32: 稀有 | AB32: 工具
L33: 生化义肢被假定具有与同它们连接的身体相当的力量和敏捷（而不会出现过度用力就被从身上扯下来的情况），但由于它们的机械化构造，使得在抵抗针对该部位的伤害时，角色的坚韧加值视为 +2 。对于生化义肢的伤害视同作用于角色本身，致命效果照常计算，但撕裂武器导致的失血效果对生化义肢无效。对生化义肢造成足够的伤害同样能导致角色死亡，可以视为义肢炸裂的碎片，高温，或者贮存的能量外泄等对角色造成了致命的伤害。义肢和额外肢体（例如机械附肢）功能的充分发挥依赖于角色的知识。举例而言，只有具有医疗技能的角色才能得到医疗附肢的好处。注意生化义肢的奖励和惩罚都仅在你使用它时生效。移植了两条同样的生化义肢不会使奖励翻倍。 #机械附肢是技术神甫常用的强化设备，通常装在肩部或胸部。一名技术神甫能安装的机械附肢数量不超过他的坚韧加值。 | W33: 尖叫报警器 | X33: 使用须GM暗投技术应用并成功，尖叫报警器感知属性75点，声音传播范围一公里 | Y33: 2 | Z33: 140 | AA33: 匮乏 | AB33: 工具
D34: 药物使用过量 | W34: 声波干扰器 | X34: 潜行+30，可以维持 20 分钟，之后须充能1h | Y34: 2 | Z34: 25 | AA34: 一般 | AB34: 工具
W35: 收发报机 | X35: 使用需进行+10的技术应用。 | Y35: 4 | Z35: 300 | AA35: 匮乏 | AB35: 工具
D36: 频繁服用同一种药物，尤其是在短时间内这样，会有一定几率导致药物无法正常起效。这表现为侍僧的身体开始对药物产生一定的耐药性。如果想要在 24 小时之内重复服用同一种药物，角色必须以−20的减值（反复服药减值累加）通过一次坚韧检定，如果失败，24小时之内服用同样药物不会对角色产生任何影响。 | W36: 书写工具组 | X36: 纸张，墨水，羽毛笔 | Y36: 2 | Z36: 20 | AA36: 普及 | AB36: 工具
W37: 蒸馏酒 | X37: 一种由葡萄酒蒸馏出来的酒精流行饮料 | Y37: — | Z37: 50 | AA37: 匮乏 | AB37: 工具
W38: 解毒剂（药物） | X38: 立刻终止药品毒素空气的任何影响，无论好坏，但有特例 | Y38: — | Z38: 65 | AA38: 稀有 | AB38: 工具
W39: 暴怒（药物） | X39: 1d10min狂暴天赋和无视恐惧 | Y39: — | Z39: 95 | AA39: 罕见 | AB39: 工具
W40: 注射器 | X40: 消耗完整动作储存药物 | Y40: — | Z40: 5 | AA40: 充裕 | AB40: 工具
W41: 卷烟 | X41: 具有特殊香气，微量麻醉（和上瘾）性物质 | Y41: — | Z41: 10 | AA41: 普及 | AB41: 工具
...

Sheet 车卡指南
B2: 1 .选择出生地 | P2: DH车卡战斗入门指南 指南制作者们：晨星、IAN、五三点九 引言：论扩展与规则书与本指南的使用指南 关于扩展内容是什么？ 扩展旨在丰富核心规则外的游玩体验（如新增出身、NPC及装备等），在使用扩展之前，需提前咨询你的GM。 本指南仅引用《【CBR】黑暗异端1版核心规则书》部分内容。 旨在提供一份仅供参考的DH车卡战斗流程入门指南，而非黑暗异端圣典。 强烈建议搭配“规则书本体”使用。若指南内容与规则书或 GM 的裁定有冲突，请以规则书原文或GM为准。 对于指南中未提及且无标注的扩展数据，请自行查阅对应资料文件或询问GM。 规则资料查找链接如下 黑暗异端不全书项目地址：https://github.com/VolEurr0Se/DH1e_chm/releases 使用github需要一定的灵能使用知识（懂得都懂）。 在上述地址中你可以获得规则，资源，及自动卡。 如果无法使用github↓ 翻译：译辞修会圣杯分部 【战锤40K TRPG《黑暗异端》全出身世界整合】网页地址：https://b23.tv/EmRikwu 【战锤40K TRPG《黑暗异端》全背景包整合-哔哩哔哩】网页地址： https://b23.tv/byypIYv 另外，如想交流战锤跑团相关，可以加入qq群 963502363
B4: 在四个核心规则、或扩展规则的出生地中任选其一。
B6: 它决定了你的侍僧的基础技能、属性加减值及独特特性等（详见《核心规则书》第15 页，扩展见https://b23.tv/EmRikwu）。
B8: 生涯（职业）选择范围
B10: 出生地直接限制了可选的职业（生涯）范围。如“蛮荒世界”无法选择“技术神甫”。
B12: （详见附页“出身世界和对应可选职业”）
B14: 2 .投掷属性骰
B16: 侍僧在基本生理、心理、格斗射击上的强弱。共9 项：格斗能力、射击能力、力量、坚韧、敏捷、智力、感知、意志、交际。
B18: 投掷属性
B20: 投掷2d10（网团：r9#2d10）得出属性基本值。
B22: 属性基本值+对应出身世界调整值=侍僧的基础属性值。
B24: （详见附页“出身世界和对应初始属性加成”）
B26: 一次重投机会
... B30: 属性加值
P31: =_xlfn.DISPIMG("ID_4EBE80AC15F543A096196B1DBCE013B0",1) -> =DISPIMG("ID_4EBE80AC15F543A096196B1DBCE013B0",1)
B32: 属性加值=最终属性值÷10（向下取整）。
B34: 示例：45 坚韧=坚韧+4；36 交际=交际+3。
B36: 格斗技巧（WS）
B38: 影响使用近战时的近战命中率。
B40: 远程技巧（BS）
B42: 影响使用远程、投掷时的远程命中率。
B44: 力量（S）：肌肉、力量的强度。
B46: 进行近战攻击时，伤害骰会额外加上力量加值，影响最终近战伤害。
B48: 坚韧（T）：对创伤、环境的忍耐力。
B50: 受到攻击时，需减去等同于坚韧加值的伤害，影响最终承伤。
B52: 示例：伤害7 -坚韧4 =真实伤害3。
B54: 敏捷（Ag）：速度、反应与平衡。
... B66: 意志（WP）：我是罗格·多恩。
P67: 出身世界和对应可选职业（可自由选择与出身世界相对应的可选职业，也可投掷d100随机职业）
B68: 直接决定灵能使用及灵能相关技能的成功率；同时也是恐惧判定是否成功的依据。
P69: 出身 | R69: 文员 | S69: 法务官 | T69: 杀手 | U69: 修女会 | V69: 牧师 | W69: 卫队士兵 | X69: 帝国灵能者 | Y69: 流氓 | Z69: 技术神甫
B70: 交际（Fel）：社交手腕、魅力与领导力。 | P70: 帝国世界 | R70: 01~11 | S70: 12~23 | T70: 24~33 | U70: 34~42 | V70: 43~54 | W70: 55~65 | X70: 66~77 | Y70: 78~89 | Z70: 90~100
P71: 巢都世界 | R71: 不可选 | S71: 01~17 | T71: 18~20 | U71: 不可选 | V71: 21~25 | W71: 26~35 | X71: 36~40 | Y71: 41~79 | Z71: 80~100
B72: 影响与NPC 互动时社交技能的投骰结果，影响侍僧的人际交往能力。 | P72: 蛮荒世界 | R72: 不可选 | S72: 不可选 | T72: 01~30 | U72: 不可选 | V72: 不可选 | W72: 31~80 | X72: 81~90 | Y72: 91~100 | Z72: 不可选
P73: 虚空生人 | R73: 01~10 | S73: 11~20 | T73: 21~25 | U73: 不可选 | V73: 26~35 | W73: 不可选 | X73: 36~75 | Y73: 76~85 | Z73: 86~100
B74: 属性与技能间的关系 | P74: 忠嗣学院 | R74: 01~20 | S74: 21~40 | T74: 不可选 | U74: 41~60 | V74: 61~80 | W74: 81~100 | X74: 不可选 | Y74: 不可选 | Z74: 不可选
P75: 铸造世界 | R75: 01~25 | S75: 不可选 | T75: 26~35 | U75: 不可选 | V75: 图兰舒什限定 | W75: 36~60 | X75: 伊杜梅亚限定 | Y75: 61~70 | Z75: 71~100
B76: 技能分为基础和高级两类，属性高低会直接决定对应技能的技能值，具体如下有三种情况： | P76: 贵族生人 | R76: 01~18 | S76: 19~30 | T76: 31~40 | U76: 不可选 | V76: 41~56 | W76: 57~75 | X76: 76~85 | Y76: 86~100 | Z76: 不可选
P77: 思维洗涤 | R77: 不可选 | S77: 01~15 | T77: 16~50 | U77: 不可选 | V77: 51~60 | W77: 61~80 | X77: 81~90 | Y77: 不可选 | Z77: 91~100
B78: 已受训的技能 | P78: 圣殿世界 | R78: 01~10 | S78: 11~18 | T78: 19~30 | U78: 31~55 | V78: 56~80 | W78: 81~100 | X78: 不可选 | Y78: 不可选 | Z78: 不可选
...

Sheet 机械神甫（晋升表）
C3: 表 2.15: 技术神甫属性提升 | I3: 阶级简介 | J3: 提升 | K3: 花费 | L3: 种类 | M3: 先决条件 | O3: 阶级简介 | P3: 提升 | Q3: 花费 | R3: 种类 | S3: 先决条件 | U3: 阶级简介 | V3: 提升 | W3: 花费 | X3: 种类 | Y3: 先决条件 | AA3: 阶级简介 | AB3: 提升 | AC3: 花费 | AD3: 种类 | AE3: 先决条件
I4: 仪表技工 | J4: 常识（机械教） | K4: 100 | L4: 技能 | M4: — | O4: 技术工匠 | P4: 常识(科技)+10 | Q4: 100 | R4: 技能 | S4: 常识(科技) | U4: 电子修士 | V4: 常识(机械教)+10 | W4: 100 | X4: 技能 | Y4: 常识(机械教) | AA4: 技术神甫 | AB4: 常识(内政部) | AC4: 100 | AD4: 技能 | AE4: —
C5: 属性 | D5: 初级 | E5: 中等 | F5: 熟练 | G5: 专家 | J5: 常识（科技） | K5: 100 | L5: 技能 | M5: — | P5: 爆破 | Q5: 100 | R5: 技能 | S5: — | V5: 常识(帝国国教) | W5: 100 | X5: 技能 | Y5: - | AB5: 常识(帝国国教)+10 | AC5: 100 | AD5: 技能 | AE5: 常识(帝国国教)
C6: 格斗能力 WS | D6: 250 | E6: 500 | F6: 750 | G6: 1000 | I6: “如果你发现了任何莫莫名其妙的故障，就交给仪表技工去办。他会把毛病找出来的。” | J6: 驾驶（地面载具） | K6: 100 | L6: 技能 | M6: — | O6: “滑车底部爆炸……卜兹兹兹……五具支架倒塌……喀兹兹兹……任务不能失败……兹喀喀喀……技工小队立即行动!” | P6: 暗号(侍僧) | Q6: 100 | R6: 技能 | S6: — | U6: “我听不懂他在说什么,但那个电子修士头巾下面开始有红光闪动,之后它碰了他一下,然后随着一声巨响,他就飞过了屋子另一头!要不是这样就让皇帝弄瞎我的眼睛!我就知道他们严密看守发电机神殿是有原因的!” | V6: 常识(帝国国教) | W6: 100 | X6: 技能 | Y6: - | AA6: “他站在扇叶前,看起来懦弱又谦卑。用技术神甫的话说,他在启动引擎,好让巢都能呼吸顺畅。他用靴子反复敲出神圣的节奏,之后看哪!风扇开始转动了。” | AB6: 常识(帝国)+10 | AC6: 100 | AD6: 技能 | AE6: 常识(帝国)
C7: 射击能力 BS | D7: 250 | E7: 500 | F7: 750 | G7: 1000 | J7: 估价 | K7: 100 | L7: 技能 | M7: — | P7: 驾驶(地面载具)+10 | Q7: 100 | R7: 技能 | S7: 驾驶(地面载具) | V7: 驾驶(地面载具)+20 | W7: 100 | X7: 技能 | Y7: 驾驶(地面载具)+10 | AB7: 常识(科技)+20 | AC7: 100 | AD7: 技能 | AE7: 常识(科技)+10
C8: 力量 S | D8: 500 | E8: 750 | F8: 1000 | G8: 2500 | J8: 禁忌知识（机械神教） | K8: 100 | L8: 技能 | M8: — | P8: 驾驶(步行载具) | Q8: 100 | R8: 技能 | S8: — | V8: 驾驶(悬浮载具) | W8: 100 | X8: 技能 | Y8: - | AB8: 驾驶(悬浮载具)+20 | AC8: 100 | AD8: 技能 | AE8: 驾驶(悬浮载具)+10
C9: 坚韧 T | D9: 100 | E9: 250 | F9: 500 | G9: 750 | J9: 阅读 | K9: 100 | L9: 技能 | M9: — | P9: 医疗 | Q9: 100 | R9: 技能 | S9: — | V9: 驾驶(步行载具)+10 | W9: 100 | X9: 技能 | Y9: 驾驶(步行载具) | AB9: 禁忌知识(古代科技) | AC9: 100 | AD9: 技能 | AE9: —
C10: 敏捷 Ag | D10: 500 | E10: 750 | F10: 1000 | G10: 2500 | J10: 阅读+10 | K10: 100 | L10: 技能 | M10: 阅读 | P10: 学术知识(化学) | Q10: 100 | R10: 技能 | S10: — | V10: 禁忌知识 | W10: 100 | X10: 技能 | Y10: 禁忌知识(机械神教) | AB10: 禁忌知识(机械神教)+20 | AC10: 100 | AD10: 技能 | AE10: 禁忌知识(机械神教)+10
C11: 智力 Int | D11: 100 | E11: 250 | F11: 500 | G11: 750 | I11: 为了更好地理解机械神欧姆尼塞亚,仪表技工需要学习各种型号,产品,以及形式。他们可以轻易编目与检索任何科技产品。 | J11: 逻辑 | K11: 100 | L11: 技能 | M11: — | P11: 入侵 | Q11: 100 | R11: 技能 | S11: — | V11: (机械神教)+10 | AA11: 技术神甫开始发掘深层次的科技奥秘,并通晓很多维持仪式,发动仪式,重新启动仪式等等。从简单的机械门到从废墟中发掘出来的远古科技,技术神甫都能在它们身上发现机械神的形象,并为将更多的知识添加到机械神教的数据室中。 | AB11: 逻辑+20 | AC11: 100 | AD11: 技能 | AE11: 逻辑+10
C12: 感知 Per | D12: 250 | E12: 500 | F12: 750 | G12: 1000 | J12: 航行(民用飞行器) | K12: 100 | L12: 技能 | M12: — | O12: 技术工匠了解各种材料的性质。他们负责大规模修理工作,维护危险的制造程序。 | P12: 技术应用+10 | Q12: 100 | R12: 技能 | S12: 技术应用 | U12: 对形态和材料配比了如指掌之后,电子修士开始投身于能源的研究。自此他们钻研机械本灵的活动法则,以及安抚它们的方法。 | V12: 阅读+20 | W12: 100 | X12: 技能 | Y12: 阅读+10 | AB12: 学术知识(古代史) | AC12: 100 | AD12: 技能 | AE12: —
C13: 意志 WP | D13: 100 | E13: 250 | F13: 500 | G13: 750 | J13: 密语(科技) | K13: 100 | L13: 技能 | M13: — | P13: 生计(矿工) | Q13: 100 | R13: 技能 | S13: — | V13: 逻辑+10 | W13: 100 | X13: 技能 | Y13: 逻辑 | AB13: 学术知识(化学)+20 | AC13: 100 | AD13: 技能 | AE13: 学术知识(化学)+10
C14: 交际 Fel | D14: N/A | E14: N/A | F14: N/A | G14: N/A | J14: 生计(抄写员) | K14: 100 | L14: 技能 | M14: — | P14: 生计(铁匠) | Q14: 100 | R14: 技能 | S14: — | V14: 学术知识(数字学) | W14: 100 | X14: 技能 | Y14: - | AB14: 学术知识(帝国国教) | AC14: 100 | AD14: 技能 | AE14: —
J15: 生计(雕刻师) | K15: 100 | L15: 技能 | M15: — | P15: 生计(技师) | Q15: 100 | R15: 技能 | S15: — | V15: 听说语言(高歌特语) | W15: 100 | X15: 技能 | Y15: - | AB15: 学术知识(帝国战术) | AC15: 100 | AD15: 技能 | AE15: —
D16: 仪表技工 | J16: 技术应用 | K16: 100 | L16: 技能 | M16: — | P16: 生计(军械师) | Q16: 100 | R16: 技能 | S16: - | V16: 密语(科技)+10 | W16: 100 | X16: 技能 | Y16: 密语(科技) | AB16: 入侵+20 | AC16: 100 | AD16: 技能 | AE16: 入侵+10
D17: xp level | E17: 0-499 | J17: 基础武器训练(原始) | K17: 100 | L17: 天赋 | M17: — | P17: 武器熟悉 | Q17: 100 | R17: 天赋 | S17: BS 30,基本武器训练(任意两种) | V17: 生计(设计师) | W17: 100 | X17: 技能 | Y17: - | AB17: 听说语言 | AC17: 100 | AD17: 技能 | AE17: 听说语言
D18: 技术工匠 | J18: 基础武器训练(激光) | K18: 100 | L18: 天赋 | M18: — | P18: 准确射击 | Q18: 100 | R18: 天赋 | S18: BS 30 | V18: 致命射击 | W18: 100 | X18: 天赋 | Y18: BS 40 | AB18: (高歌特语)+10 | AE18: (高歌特语)
D19: xp level | E19: 500-999 | J19: 基础武器训练(实体弹) | K19: 100 | L19: 天赋 | M19: — | P19: 强化五感(视觉) | Q19: 100 | R19: 天赋 | S19: - | V19: 电子援助 | W19: 100 | X19: 天赋 | Y19: 技术神甫 | AB19: 密语(科技)+20 | AC19: 100 | AD19: 技能 | AE19: 密语(科技)+10
D20: 电子修士 | J20: 机械语言者 | K20: 100 | L20: 天赋 | M20: — | P20: 铁头 | Q20: 100 | R20: 天赋 | S20: T 40 | V20: 强化五感(听觉) | W20: 100 | X20: 天赋 | Y20: - | AB20: 技术应用+20 | AC20: 100 | AD20: 技能 | AE20: 技术应用+10
D21: xp level | E21: 1000-2999 | J21: 生化阉割 | K21: 100 | L21: 天赋 | M21: — | P21: 线圈充能 | Q21: 100 | R21: 天赋 | S21: 技术神甫 | V21: 强化五感(触觉) | W21: 100 | X21: 天赋 | Y21: - | AB21: 生计(技师)+20 | AC21: 100 | AD21: 技能 | AE21: 生计(技师)+10
D22: 工程师 | J22: 电子接口应用 | K22: 100 | L22: 天赋 | M22: — | P22: 拟声高手 | Q22: 100 | R22: 天赋 | S22: - | V22: 鲤鱼打挺 | W22: 100 | X22: 天赋 | Y22: Ag 30 | AB22: 生计(设计师)+20 | AC22: 100 | AD22: 技能 | AE22: 生计(设计师)+10
D23: xp level | E23: 2000-2999 | J23: 尖锐噪音 | K23: 100 | L23: 天赋 | M23: 技术神甫 | P23: 平等待遇(机械神教) | Q23: 100 | R23: 天赋 | S23: Fel 30 | V23: 机械附肢(多功能) | W23: 100 | X23: 天赋 | Y23: 技术神甫 | AB23: 生计(军械师)+20 | AC23: 100 | AD23: 技能 | AE23: 生计(军械师)+10
D24: 技术神甫 | J24: 轻度睡眠 | K24: 100 | L24: 天赋 | M24: Per 30 | P24: 即时备战 | Q24: 100 | R24: 天赋 | S24: - | V24: 悍不畏死 | W24: 100 | X24: 天赋 | Y24: - | AB24: 剑术大师 | AC24: 100 | AD24: 天赋 | AE24: WS 30,格斗武器训练(任意)
D25: xp level | E25: 3000-5999 | J25: 格斗武器训练(原始) | K25: 100 | L25: 天赋 | M25: — | P25: 健壮体格 | Q25: 100 | R25: 天赋 | S25: - | V25: 健壮体格 | W25: 100 | X25: 天赋 | Y25: - | AB25: 格斗专家 | AC25: 100 | AD25: 天赋 | AE25: WS 30
B26: 技术巫师 | F26: 机械执事 | J26: 手枪训练(原始) | K26: 100 | L26: 天赋 | M26: — | P26: 盲斗 | Q26: 200 | R26: 天赋 | S26: Per 30 | V26: 植入电脑 | W26: 100 | X26: 天赋 | Y26: — | AB26: 恼人嗓音 | AC26: 100 | AD26: 天赋 | AE26: —
B27: xp level | C27: 6000-7999 | F27: xp level | G27: 6000-7999 | J27: 手枪训练(激光) | K27: 100 | L27: 天赋 | M27: — | P27: 线圈放电 | Q27: 200 | R27: 天赋 | S27: 技术神甫 | V27: 密语（侍僧） | W27: 200 | X27: 技能 | Y27: — | AB27: 能量缓冲 | AC27: 100 | AD27: 天赋 | AE27: 技术神甫
B28: 运算先知 | F28: 机械神教传教士 | J28: 手枪训练(实体弹) | K28: 100 | L28: 天赋 | M28: — | V28: 基础武器训练（爆矢） | W28: 200 | X28: 天赋 | Y28: — | AB28: 独立目标 | AC28: 100 | AD28: 天赋 | AE28: BS 40
B29: xp level | C29: 8000-9999 | F29: xp level | G29: 8000-9999 | J29: 快速上膛 | K29: 100 | L29: 天赋 | M29: — | V29: 基础武器训练（榴弹） | W29: 200 | X29: 天赋 | Y29: — | AB29: 敬畏仪式 | AC29: 100 | AD29: 天赋 | AE29: 技术神甫
B30: 铸造者 | F30: 漫游锻师 | J30: 健壮体格† | K30: 100 | L30: 天赋 | M30: — | V30: 线圈冲击 | W30: 200 | X30: 天赋 | Y30: 技术神甫 | AB30: 健壮体格 | AC30: 100 | AD30: 天赋 | AE30: —
B31: xp level | C31: 10000-14999 | F31: xp level | G31: 10000-14999 | J31: 一敲就好 | K31: 100 | L31: 天赋 | M31: — | V31: 机械附肢（医疗） | W31: 200 | X31: 天赋 | Y31: 技术神甫 | AB31: 迅捷攻击 | AC31: 100 | AD31: 天赋 | AE31: WS 35
J32: 投掷武器训练(原始) | K32: 300 | L32: 天赋 | M32: — | V32: 格斗武器训练（震击） | W32: 200 | X32: 天赋 | Y32: — | AB32: 航行(宇宙飞船) | AC32: 200 | AD32: 技能 | AE32: —
J33: 可重复选择,当前阶级最多两次 | V33: 手枪训练（爆矢） | W33: 200 | X33: 天赋 | Y33: — | AB33: 基础武器训练(热熔) | AC33: 200 | AD33: 天赋 | AE33: —
AB34: 基础武器训练(等离子) | AC34: 200 | AD34: 天赋 | AE34: —
I35: 阶级简介 | J35: 提升 | K35: 花费 | L35: 种类 | M35: 先决条件 | O35: 阶级简介 | P35: 提升 | Q35: 花费 | R35: 种类 | S35: 先决条件 | U35: 阶级简介 | V35: 提升 | W35: 花费 | X35: 种类 | Y35: 先决条件 | AB35: 重型武器训练(爆矢) | AC35: 200 | AD35: 天赋 | AE35: —
I36: 技术巫师 | J36: 暗号(秘会) | K36: 100 | L36: 技能 | M36: 暗号(秘会) | O36: 运算先知 | P36: 常识(法务部)+10 | Q36: 100 | R36: 技能 | S36: 常识(法务部) | U36: 铸造者 | V36: 禁忌知识 | W36: 100 | X36: 技能 | Y36: 禁忌知识 | AB36: 磁力优雅 | AC36: 200 | AD36: 天赋 | AE36: 技术神甫
J37: 常识(法务部) | K37: 100 | L37: 技能 | M37: — | P37: 常识(国教教义)+10 | Q37: 100 | R37: 技能 | S37: 常识(国教教义) | V37: (古代科技)+20 | Y37: (古代科技)+10 | AB37: 格斗武器训练(能量) | AC37: 200 | AD37: 天赋 | AE37: —
I38: “他们意志犀利如匕首,又知道如何与内政部打交道。记住,别惹技术巫师,尤其当你在飞船上工作时。否则你会被分配到一个漏气的舱室,甚至来不及在胸前划个双头鹰。” | J38: 常识(国教教义) | K38: 100 | L38: 技能 | M38: — | O38: “他们已经很难再算是人类了。我是说,他们比技术神甫们更进一步。没人愿意把那些......你知道......危险的零件整天装在脑袋上。” | P38: 禁忌知识(古代科技)+10 | Q38: 100 | R38: 技能 | S38: 禁忌知识(古代科技) | U38: “机械神教铸造者的知识范围不广,但极有深度。每一个都是某一领域的领头专家,大多以其睿智和执着著称。” | V38: 禁忌知识(恶魔) | W38: 100 | X38: 技能 | Y38: - | AB38: 机械附肢(枪械) | AC38: 200 | AD38: 天赋 | AE38: 技术神甫
J39: 常识(帝国国教)+20 | K39: 100 | L39: 技能 | M39: 常识(帝国国教)+10 | P39: 禁忌知识(亚空间) | Q39: 100 | R39: 技能 | S39: - | V39: 禁忌知识(异端) | W39: 100 | X39: 技能 | Y39: - | AB39: 闪避 | AC39: 300 | AD39: 技能 | AE39: —
J40: 常识(帝国)+20 | K40: 100 | L40: 技能 | M40: 常识(帝国)+10 | P40: 学术知识(行政)+10 | Q40: 100 | R40: 技能 | S40: 学术知识(行政) | V40: 禁忌知识(审判庭) | W40: 100 | X40: 技能 | Y40: - | AB40: 指挥 | AC40: 300 | AD40: 技能 | AE40: —
J41: 估价+20 | K41: 100 | L41: 技能 | M41: 估价+10 | P41: 学术知识(法律)+10 | Q41: 100 | R41: 技能 | S41: 学术知识(法律) | V41: 禁忌知识(灵能者) | W41: 100 | X41: 技能 | Y41: - | AB41: 搜集信息 | AC41: 300 | AD41: 技能 | AE41: —
J42: 审讯 | K42: 100 | L42: 技能 | M42: — | P42: 学术知识(传说) | Q42: 100 | R42: 技能 | S42: - | V42: 禁忌知识(亚空间)+10 | W42: 100 | X42: 技能 | Y42: 禁忌知识(亚空间) | AB42: 恐吓 | AC42: 300 | AD42: 技能 | AE42: —
...

Sheet 自填扩展
A1: 自填并入自动化 近战武器（当前版本生效） | J1: 自填并入自动化 远程武器（当前版本生效） | V1: 自填并入自动化 天赋记录（当前版本生效）
A2: 名称 | B2: 类型 | C2: 射程 | D2: 伤害 | E2: 破甲 | F2: 特性 | G2: 重量 | H2: 花费 | J2: 名称 | K2: 类型 | L2: 射程 | M2: 射速 | N2: 伤害 | O2: 破甲 | P2: 弹容 | Q2: 装填 | R2: 特性 | S2: 重量 | T2: 花费 | V2: 名称 | W2: 具体

Sheet 职业数据
A1: 生涯职业 | B1: 起始资金 | C1: 骰点倍数 | D1: 骰点范围 | E1: 社会阶级 | F1: 王座币/月 | G1: 等级提升 | J1: 生涯职业 | K1: 文研员 | L1: 法务官 | M1: 杀手 | N1: 牧师 | O1: 卫队士兵 | P1: 帝国灵能者 | Q1: 流氓 | R1: 技术神甫 | S1: 战斗修女 | U1: =IF(人物!D3="","",IF(人物!Q4>=10000,8,IF(人物!Q4>=8000,7,IF(人物!Q4>=6000,6,IF(人物!Q4>=3000,5,IF(人物!Q4>=2000,4,IF(人物!Q4>=1000,3,IF(人物!Q4>=500,2,IF(人物!Q4>=1,1,"")))))))))
A2: 文研员 | B2: 100 | C2: 1 | D2: D10 | E2: 行伍（卫队士兵） | F2: 50 | G2: 5 | J2: 文研员 | K2: 档案员 | L2: 警员 | M2: 雇佣打手 | N2: 新信徒 | O2: 动员兵 | P2: 净化者 | Q2: 人渣 | R2: 仪表技工
A3: 执法者/法务官 | B3: 50 | C3: 2 | D3: D10 | E3: 仆役（法务官、灵能者） | F3: 70 | G3: 7 | J3: 执法者 | K3: 公证人 | L3: 治安队员 | M3: 潜行者 | N3: 入信者 | O3: 护卫队 | P3: 新生者 | Q3: 无赖 | R3: 技术工匠
A4: 杀手 | B4: 120 | C4: 3 | D4: D10 | E4: 学者（文研员） | F4: 100 | G4: 10 | J4: 杀手 | K4: 著述者 | L4: 探员 | M4: 夜鹰 | N4: 僧侣 | O4: 常备军 | P4: 候选人 | Q4: 不法分子 | R4: 电子修士
A5: 牧师 | B5: 300 | C5: 5 | D5: D10 | E5: 商人（杀手） | F5: 120 | G5: 12 | J5: 牧师 | K5: 作者 | L5: 调查员 | M5: 独行客 | N5: 传教士 | O5: 军士 | P5: 战斗术士 | Q5: 叛逆者 | R5: 工程师
A6: 卫队士兵 | B6: 70 | C6: 1 | D6: D10 | E6: 技术（技术神甫） | F6: 150 | G6: 15 | J6: 卫队士兵 | K6: 医师 | L6: 执法者 | M6: 刺客 | N6: 牧师 | O6: 老兵 | P6: 授权术士 | Q6: 浪人 | R6: 技术神甫
A7: 帝国灵能者 | B7: 50 | C7: 1 | D7: D5 | E7: 宗教（牧师） | F7: 200 | G7: 20 | J7: 帝国灵能者 | K7: 学者 | L7: 督战员 | M7: 刽子手 | N7: 告解神父 | O7: 突击队老兵 | P7: 术士中尉 | Q7: 歹徒 | R7: 技术巫师
A8: 流氓 | B8: 10 | C8: 1 | D8: D5 | E8: 贵族 | F8: 500 | G8: 50 | J8: 流氓 | K8: 律法编撰人 | L8: 司法官 | M8: 虚无者 | N8: 主教 | O8: 闪电战士 | P8: 辅战术士 | Q8: 劫匪 | R8: 运算先知
A9: 技术神甫 | B9: 150 | C9: 1 | D9: D10 | J9: 技术神甫 | K9: 学术专家 | L9: 司法长 | M9: 死亡君主 | N9: 圣师 | O9: 暴风突击队员 | P9: 参谋术士 | Q9: 龙头老大 | R9: 铸造者
A10: 战斗修女 | B10: 50 | C10: 0 | D10: 0 | J10: 战斗修女 | K10: 师范 | L10: 情报员 | M10: 自由之刃 | N10: 驱魔师 | O10: 中尉 | P10: 元素学者 | Q10: 仲介人 | R10: 机械执事
K11: 审计员 | L11: 治安官 | M11: 执照刺客 | N11: 狂信者 | O11: 队长 | P11: 生体学者 | Q11: 老油条 | R11: 机械神传教士
K12: 分析员 | L12: 审判长 | M12: 刺客统领 | N12: 赎罪者 | O12: 指挥官 | P12: 奥秘学者 | Q12: 诈骗高手 | R12: 漫游锻师
K13: 贤者 | O13: 侦察兵 | P13: 禁忌学者
O14: 射手 | P14: 至高学者
O15: 狙击手
J18: 文研员背景包 | K18: 法务官背景包 | L18: 杀手背景包 | M18: 牧师背景包 | N18: 卫队士兵背景包 | O18: 帝国灵能者背景包 | P18: 流氓背景包 | Q18: 技术神甫背景包 | R18: 战斗修女背景包
J19: 军务部军需官 | K19: 卡利西斯型谋杀 | L19: 星海锋刃 | M19: 塔苏斯至圣经院 | N19: 玛拉登陆点大屠杀 | O19: 魂覆暗影 | P19: 野兽屋奴商 | Q19: 图勒门徒 | R19: 戴罪之身
J20: 言究学社学者 | K20: 大锡诺菲亚空心人 | L20: 谋杀歌者 | M20: 托钵传教士 | N20: 边际远征军 | O20: 神皇之光指引 | P20: 冷行会情报员 | Q20: 索雷克斯圣光教 | R20: 赎罪者
J21: 虚空商贸员 | K21: 卢格南的红窟 | L21: 冥父之子 | M21: 救赎教派布焰使 | N21: 特伦奇战争老兵 | O21: 活梦魇 | P21: 托罗斯联盟 | Q21: 玛琉格利斯技术异端 | R21: 不可接触者
J22: 赎罪者 | K22: 正义，而非法律 | L22: 赎罪者 | M22: 异端教派 | N22: 赎罪者 | O22: 赎罪者 | P22: 赎罪者 | Q22: 赎罪者 | R22: 蒙福降生
J23: 持尔真名 | K23: 赎罪者 | L23: 不可接触者 | M23: 赎罪者 | N23: 不可接触者 | O23: 亚空间侵染 | P23: 不可接触者 | Q23: 不可接触者 | R23: 皈依者
J24: 不可接触者 | K24: 不可接触者 | L24: 亚空间侵染 | M24: 不可接触者 | N24: 亚空间侵染 | O24: 皈依者 | P24: 亚空间侵染 | Q24: 亚空间侵染 | R24: 朝圣者
J25: 亚空间侵染 | K25: 亚空间侵染 | L25: 命线缠绕 | M25: 亚空间侵染 | N25: 命线缠绕 | O25: 朝圣者 | P25: 命线缠绕 | Q25: 皈依者 | R25: 血肉圣化
J26: 命线缠绕 | K26: 命线缠绕 | L26: 皈依者 | M26: 命线缠绕 | N26: 皈依者 | O26: 血肉圣化 | P26: 皈依者 | Q26: 背弃万机神之人 | R26: 降魔者
J27: 皈依者 | K27: 皈依者 | L27: 朝圣者 | M27: 蒙福降生 | N27: 朝圣者 | O27: 降魔者 | P27: 朝圣者 | Q27: 血肉圣化 | R27: 宿命噬者
J28: 朝圣者 | K28: 朝圣者 | L28: 血肉圣化 | M28: 皈依者 | N28: 得见神迹 | O28: 宿命噬者 | P28: 血肉圣化 | Q28: 降魔者 | R28: 宿主备身
J29: 血肉圣化 | K29: 血肉圣化 | L29: 降魔者 | M29: 朝圣者 | N29: 血肉圣化 | O29: 巢都马仔 | P29: 降魔者 | Q29: 宿命噬者 | R29: 冒充者
J30: 降魔者 | K30: 降魔者 | L30: 宿命噬者 | M30: 血肉圣化 | N30: 降魔者 | O30: 冒充者 | P30: 宿命噬者 | Q30: 冷贸易商 | R30: 无罪证明
J31: 宿命噬者 | K31: 宿命噬者 | L31: 宿主备身 | M31: 降魔者 | N31: 宿命噬者 | O31: 无罪证明 | P31: 宿主备身 | Q31: 冒充者
J32: 宿主备身 | K32: 宿主备身 | L32: 冷贸易商 | M32: 宿命噬者 | N32: 宿主备身 | P32: 冷贸易商 | Q32: 无罪证明
J33: 冷贸易商 | K33: 执法者 | L33: 执法者 | M33: 宿主备身 | N33: 巢都马仔 | P33: 执法者 | Q33: 西贝柳斯拾荒者
J34: 执法者 | K34: 冒充者 | L34: 巢都马仔 | M34: 冷贸易商 | N34: 冒充者 | P34: 巢都马仔 | Q34: 底巢商人
J35: 冒充者 | K35: 无罪证明 | L35: 冒充者 | M35: 冒充者 | N35: 无罪证明 | P35: 冒充者
J36: 卡斯巴利卡“贵族” | K36: 西贝柳斯拾荒者 | L36: 无罪证明 | M36: 无罪证明 | N36: 西贝柳斯拾荒者 | P36: 卡斯巴利卡“贵族”
J37: 无罪证明 | K37: 底巢商人 | M37: 底巢商人 | N37: 底巢商人 | P37: 无罪证明
J38: 西贝柳斯拾荒者 | P38: 西贝柳斯拾荒者
J39: 底巢商人 | P39: 底巢商人

Sheet 人物数据
A1: 出目 | B1: 预言 | C1: 影响 | D1: SB+TB | E1: 携带 | F1: 举起 | G1: 拖拽 | H1: 缩写 | I1: AB | J1: 部分移动 | K1: 完整移动 | L1: 冲刺 | M1: 奔跑 | N1: 每分钟 | O1: 每小时 | P1: 每天 | Q1: 体型 | R1: 检定调整 | S1: 起源 | T1: {=_xlfn.UNIQUE(灵能表[灵能类别])} -> 次级灵能 | U1: {=IFERROR(_xlfn._xlws.FILTER(灵能表[灵能名称],灵能表[灵能类别]=灵能!E11),"")} | V1: {=_xlfn.UNIQUE(_xlfn._xlws.FILTER(_xlfn.VSTACK(武器与防具与弹药!B6:I24,自填扩展!A3:H60),INDEX(_xlfn.VSTACK(武器与防具与弹药!B6:I24,自填扩展!A3:H60),,1)<>""))} -> 斧 | W1: 格斗 | X1: — | Y1: 1d10+1 R | Z1: 0 | AA1: 原始，失衡 | AB1: 4 | AC1: 20 | AE1: {=_xlfn.UNIQUE(_xlfn._xlws.FILTER(_xlfn.VSTACK(武器与防具与弹药!B27:L63,自填扩展!J3:T60),INDEX(_xlfn.VSTACK(武器与防具与弹药!B27:L63,自填扩展!J3:T60),,1)<>""))} -> 激光手枪 | AF1: 手枪 | AG1: 30m | AH1: S/–/– | AI1: 1d10+2 E | AJ1: 0 | AK1: 30 | AL1: 完整 | AM1: 可靠 | AN1: 1.5 | AO1: 50 | AQ1: {=_xlfn.UNIQUE(_xlfn._xlws.FILTER(_xlfn.VSTACK(附表!W3:X126,自填扩展!V3:W60),INDEX(_xlfn.VSTACK(附表!W3:X126,自填扩展!V3:W60),,1)<>""))} -> 傲慢护甲 | AR1: 你将自己包裹在由轻蔑与憎恶织就的护甲里。每次得到堕落点时，你都可以抵抗掉1点。另外，作为一个自由动作，你可以进行一个意志检定以尝试在一轮之内忽略你积累的堕落的影响。 | AW1: =_xlfn.IFNA(IF(人物!B98=0,"",VLOOKUP(人物!B98,人物数据!$AQ$1:人物数据!$AR$300,2,FALSE)),"") | BB1: =_xlfn.IFNA(IF(武备!B20=0,"",VLOOKUP(武备!B20,武器与防具与弹药!$B$66:武器与防具与弹药!$H$91,2,FALSE)),"") | BC1: =_xlfn.IFNA(IF(武备!B20=0,"",VLOOKUP(武备!B20,武器与防具与弹药!$B$66:武器与防具与弹药!$H$91,3,FALSE)),"") | BD1: =_xlfn.IFNA(IF(武备!B20=0,"",VLOOKUP(武备!B20,武器与防具与弹药!$B$66:武器与防具与弹药!$H$91,4,FALSE)),"") | BE1: =_xlfn.IFNA(IF(武备!B20=0,"",VLOOKUP(武备!B20,武器与防具与弹药!$B$66:武器与防具与弹药!$H$91,5,FALSE)),"") | BF1: =_xlfn.IFNA(IF(武备!B20=0,"",VLOOKUP(武备!B20,武器与防具与弹药!$B$66:武器与防具与弹药!$H$91,6,FALSE)),"") | BG1: =_xlfn.IFNA(IF(武备!B20=0,"",VLOOKUP(武备!B20,武器与防具与弹药!$B$66:武器与防具与弹药!$H$91,7,FALSE)),"") | BI1: =_xlfn.IFNA(IF(武备!B35=0,"",VLOOKUP(武备!B35,武器与防具与弹药!$AI$6:武器与防具与弹药!$AM$32,2,FALSE)),"") | BJ1: =_xlfn.IFNA(IF(武备!B35=0,"",VLOOKUP(武备!B35,武器与防具与弹药!$AI$6:武器与防具与弹药!$AM$32,3,FALSE)),"") | BK1: =_xlfn.IFNA(IF(武备!B35=0,"",VLOOKUP(武备!B35,武器与防具与弹药!$AI$6:武器与防具与弹药!$AM$32,4,FALSE)),"") | BL1: =_xlfn.IFNA(IF(武备!B35=0,"",VLOOKUP(武备!B35,武器与防具与弹药!$AI$6:武器与防具与弹药!$AM$32,5,FALSE)),"") | BN1: =_xlfn.IFNA(IF(武备!C43=0,"",VLOOKUP(武备!C43,附表!AC2:附表!AF61,2,FALSE)),"") | BO1: =_xlfn.IFNA(IF(武备!C43=0,"",VLOOKUP(武备!C43,附表!$AC$2:附表!$AF$61,3,FALSE)),"") | BP1: =_xlfn.IFNA(IF(武备!C43=0,"",VLOOKUP(武备!C43,附表!$AC$2:附表!$AF$61,4,FALSE)),"") | BR1: =_xlfn.IFNA(IF(武备!K75=0,"",VLOOKUP(武备!K75,附表!$AJ$53:附表!$AM$64,2,FALSE)),"") | BU1: {=_xlfn.IFNA(IF(武备!B4=0,"",VLOOKUP(武备!B4,人物数据!$V$1:$AC$300,{1,2,3,4,5,6,7,8},FALSE)),"")} | CD1: {=_xlfn.IFNA(IF(武备!B10=0,"",VLOOKUP(武备!B10,人物数据!$AE$1:$AO$300,{1,2,3,4,5,6,7,8,9,10,11},FALSE)),"")} | CP1: {=_xlfn.IFNA(IF(人物!T65=0,"",VLOOKUP(人物!T65,附表!$B$70:$D$118,{1,2,3},FALSE)),"")}
A2: 1 | B2: 外表的变异，揭示着内心的腐化。 | C2: 以一个次级变异状态开始游戏。 | D2: 0 | E2: 0.9 | F2: 2.25 | G2: 4.5 | H2: 格 | I2: 0 | J2: 0 | K2: 0 | L2: 0 | M2: =6*I2 -> 0 | N2: 12m | O2: 0.75km | P2: 7km | Q2: 微小 | R2: -30 | S2: 帝国世界 | T2: 生化学科 | V2: 黄铜指虎 | W2: 格斗 | X2: — | Y2: 1d5−1 I | Z2: 0 | AA2: 原始 | AB2: 0.5 | AC2: 5 | AE2: 激光卡宾枪 | AF2: 基本 | AG2: 60m | AH2: S/2/– | AI2: 1d10+2 E | AJ2: 0 | AK2: 40 | AL2: 完整 | AM2: 可靠 | AN2: 3 | AO2: 75 | AQ2: 拨挡飞箭 | AR2: 你可以格挡投掷武器或原始远程武器。 | AW2: =_xlfn.IFNA(IF(人物!B99=0,"",VLOOKUP(人物!B99,人物数据!$AQ$1:人物数据!$AR$300,2,FALSE)),"") | BB2: =_xlfn.IFNA(IF(武备!B21=0,"",VLOOKUP(武备!B21,武器与防具与弹药!$B$66:武器与防具与弹药!$H$91,2,FALSE)),"") | BC2: =_xlfn.IFNA(IF(武备!B21=0,"",VLOOKUP(武备!B21,武器与防具与弹药!$B$66:武器与防具与弹药!$H$91,3,FALSE)),"") | BD2: =_xlfn.IFNA(IF(武备!B21=0,"",VLOOKUP(武备!B21,武器与防具与弹药!$B$66:武器与防具与弹药!$H$91,4,FALSE)),"") | BE2: =_xlfn.IFNA(IF(武备!B21=0,"",VLOOKUP(武备!B21,武器与防具与弹药!$B$66:武器与防具与弹药!$H$91,5,FALSE)),"") | BF2: =_xlfn.IFNA(IF(武备!B21=0,"",VLOOKUP(武备!B21,武器与防具与弹药!$B$66:武器与防具与弹药!$H$91,6,FALSE)),"") | BG2: =_xlfn.IFNA(IF(武备!B21=0,"",VLOOKUP(武备!B21,武器与防具与弹药!$B$66:武器与防具与弹药!$H$91,7,FALSE)),"") | BI2: =_xlfn.IFNA(IF(武备!B36=0,"",VLOOKUP(武备!B36,武器与防具与弹药!$AI$6:武器与防具与弹药!$AM$32,2,FALSE)),"") | BJ2: =_xlfn.IFNA(IF(武备!B36=0,"",VLOOKUP(武备!B36,武器与防具与弹药!$AI$6:武器与防具与弹药!$AM$32,3,FALSE)),"") | BK2: =_xlfn.IFNA(IF(武备!B36=0,"",VLOOKUP(武备!B36,武器与防具与弹药!$AI$6:武器与防具与弹药!$AM$32,4,FALSE)),"") | BL2: =_xlfn.IFNA(IF(武备!B36=0,"",VLOOKUP(武备!B36,武器与防具与弹药!$AI$6:武器与防具与弹药!$AM$32,5,FALSE)),"") | BN2: =_xlfn.IFNA(IF(武备!C44=0,"",VLOOKUP(武备!C44,附表!$AC$2:附表!$AF$61,2,FALSE)),"") | BO2: =_xlfn.IFNA(IF(武备!C44=0,"",VLOOKUP(武备!C44,附表!$AC$2:附表!$AF$61,3,FALSE)),"") | BP2: =_xlfn.IFNA(IF(武备!C44=0,"",VLOOKUP(武备!C44,附表!$AC$2:附表!$AF$61,4,FALSE)),"") | BR2: =_xlfn.IFNA(IF(武备!K76=0,"",VLOOKUP(武备!K76,附表!$AJ$53:附表!$AM$64,2,FALSE)),"") | BU2: {=_xlfn.IFNA(IF(武备!B5=0,"",VLOOKUP(武备!B5,人物数据!$V$1:$AC$300,{1,2,3,4,5,6,7,8},FALSE)),"")} | CD2: {=_xlfn.IFNA(IF(武备!B12=0,"",VLOOKUP(武备!B12,人物数据!$AE$1:$AO$300,{1,2,3,4,5,6,7,8,9,10,11},FALSE)),"")} | CP2: {=_xlfn.IFNA(IF(人物!T78=0,"",VLOOKUP(人物!T78,附表!$B$70:$D$118,{1,2,3},FALSE)),"")}
A3: 2 | B3: 只有疯狂者才有成功所需的力量，只有成功者才有权定义何为理智。 | C3: 以2点失心点数状态开始游戏。 | D3: 1 | E3: 2.25 | F3: 4.5 | G3: 9 | H3: 射 | I3: 1 | J3: 1 | K3: 2 | L3: 3 | M3: =6*I3 -> 6 | N3: 24m | O3: 1.5km | P3: 15km | Q3: 超小 | R3: -20 | S3: 马卡贝斯五号 | T3: 预言学科 | V3: 棍棒 | W3: 格斗 | X3: — | Y3: 1d10 I | Z3: 0 | AA3: 原始 | AB3: 2 | AC3: 5 | AE3: 激光步枪 | AF3: 基本 | AG3: 100m | AH3: S/3/– | AI3: 1d10+3 E | AJ3: 0 | AK3: 60 | AL3: 完整 | AM3: 可靠 | AN3: 4 | AO3: 75 | AQ3: 藏物暗袋 | AR3: 你身上有个用于藏匿不超过巴掌大小的物件的秘密隔间，可能是某个嵌入你体内的小袋，或是半机械移植物的一部分。一个困难（−10 ）程度的搜索检定可以发现被藏起来的物品。如果搜身者借助于医学扫描仪，生化嗅探器等设备，检定变为普通（ +10 ）。你身上有个用于藏匿不超过巴掌大小的物件的秘密隔间，可能是某个嵌入你体内的小袋，或是半机械移植物的一部分。一个困难（−10 ）程度的搜索检定可以发现被藏起来的物品。如果搜身者借助于医学扫描仪，生化嗅探器等设备，检定变为普通（ +10 ）。 | AW3: =_xlfn.IFNA(IF(人物!B100=0,"",VLOOKUP(人物!B100,人物数据!$AQ$1:人物数据!$AR$300,2,FALSE)),"") | BB3: =_xlfn.IFNA(IF(武备!B22=0,"",VLOOKUP(武备!B22,武器与防具与弹药!$B$66:武器与防具与弹药!$H$91,2,FALSE)),"") | BC3: =_xlfn.IFNA(IF(武备!B22=0,"",VLOOKUP(武备!B22,武器与防具与弹药!$B$66:武器与防具与弹药!$H$91,3,FALSE)),"") | BD3: =_xlfn.IFNA(IF(武备!B22=0,"",VLOOKUP(武备!B22,武器与防具与弹药!$B$66:武器与防具与弹药!$H$91,4,FALSE)),"") | BE3: =_xlfn.IFNA(IF(武备!B22=0,"",VLOOKUP(武备!B22,武器与防具与弹药!$B$66:武器与防具与弹药!$H$91,5,FALSE)),"") | BF3: =_xlfn.IFNA(IF(武备!B22=0,"",VLOOKUP(武备!B22,武器与防具与弹药!$B$66:武器与防具与弹药!$H$91,6,FALSE)),"") | BG3: =_xlfn.IFNA(IF(武备!B22=0,"",VLOOKUP(武备!B22,武器与防具与弹药!$B$66:武器与防具与弹药!$H$91,7,FALSE)),"") | BI3: =_xlfn.IFNA(IF(武备!B37=0,"",VLOOKUP(武备!B37,武器与防具与弹药!$AI$6:武器与防具与弹药!$AM$32,2,FALSE)),"") | BJ3: =_xlfn.IFNA(IF(武备!B37=0,"",VLOOKUP(武备!B37,武器与防具与弹药!$AI$6:武器与防具与弹药!$AM$32,3,FALSE)),"") | BK3: =_xlfn.IFNA(IF(武备!B37=0,"",VLOOKUP(武备!B37,武器与防具与弹药!$AI$6:武器与防具与弹药!$AM$32,4,FALSE)),"") | BL3: =_xlfn.IFNA(IF(武备!B37=0,"",VLOOKUP(武备!B37,武器与防具与弹药!$AI$6:武器与防具与弹药!$AM$32,5,FALSE)),"") | BN3: =_xlfn.IFNA(IF(武备!C45=0,"",VLOOKUP(武备!C45,附表!$AC$2:附表!$AF$61,2,FALSE)),"") | BO3: =_xlfn.IFNA(IF(武备!C45=0,"",VLOOKUP(武备!C45,附表!$AC$2:附表!$AF$61,3,FALSE)),"") | BP3: =_xlfn.IFNA(IF(武备!C45=0,"",VLOOKUP(武备!C45,附表!$AC$2:附表!$AF$61,4,FALSE)),"") | BR3: =_xlfn.IFNA(IF(武备!K77=0,"",VLOOKUP(武备!K77,附表!$AJ$53:附表!$AM$64,2,FALSE)),"") | BU3: {=_xlfn.IFNA(IF(武备!B6=0,"",VLOOKUP(武备!B6,人物数据!$V$1:$AC$300,{1,2,3,4,5,6,7,8},FALSE)),"")} | CD3: {=_xlfn.IFNA(IF(武备!B14=0,"",VLOOKUP(武备!B14,人物数据!$AE$1:$AO$300,{1,2,3,4,5,6,7,8,9,10,11},FALSE)),"")}
A4: 3 | B4: 只有疯狂者才有成功所需的力量，只有成功者才有权定义何为理智。 | C4: 以2点失心点数状态开始游戏。 | D4: 2 | E4: 4.5 | F4: 9 | G4: 18 | H4: 力 | I4: 2 | J4: 2 | K4: 4 | L4: 6 | M4: =6*I4 -> 12 | N4: 48m | O4: 3km | P4: 30km | Q4: 小型 | R4: -10 | S4: 锡诺菲亚 | T4: 操火学科 | V4: 链枷 | W4: 格斗† | X4: — | Y4: 1d10+2 I | Z4: 0 | AA4: 原始，柔韧 | AB4: 4 | AC4: 20 | AE4: 激光长枪 | AF4: 基本 | AG4: 150m | AH4: S/–/– | AI4: 1d10+3 E | AJ4: 1 | AK4: 40 | AL4: 完整 | AM4: 可靠，精准 | AN4: 4.5 | AO4: 100 | AQ4: 出生入死 | AR4: 只要看到你，你的下属免受恐惧和压制。 | AW4: =_xlfn.IFNA(IF(人物!B101=0,"",VLOOKUP(人物!B101,人物数据!$AQ$1:人物数据!$AR$300,2,FALSE)),"") | BB4: =_xlfn.IFNA(IF(武备!B23=0,"",VLOOKUP(武备!B23,武器与防具与弹药!$B$66:武器与防具与弹药!$H$91,2,FALSE)),"") | BC4: =_xlfn.IFNA(IF(武备!B23=0,"",VLOOKUP(武备!B23,武器与防具与弹药!$B$66:武器与防具与弹药!$H$91,3,FALSE)),"") | BD4: =_xlfn.IFNA(IF(武备!B23=0,"",VLOOKUP(武备!B23,武器与防具与弹药!$B$66:武器与防具与弹药!$H$91,4,FALSE)),"") | BE4: =_xlfn.IFNA(IF(武备!B23=0,"",VLOOKUP(武备!B23,武器与防具与弹药!$B$66:武器与防具与弹药!$H$91,5,FALSE)),"") | BF4: =_xlfn.IFNA(IF(武备!B23=0,"",VLOOKUP(武备!B23,武器与防具与弹药!$B$66:武器与防具与弹药!$H$91,6,FALSE)),"") | BG4: =_xlfn.IFNA(IF(武备!B23=0,"",VLOOKUP(武备!B23,武器与防具与弹药!$B$66:武器与防具与弹药!$H$91,7,FALSE)),"") | BI4: =_xlfn.IFNA(IF(武备!B38=0,"",VLOOKUP(武备!B38,武器与防具与弹药!$AI$6:武器与防具与弹药!$AM$32,2,FALSE)),"") | BJ4: =_xlfn.IFNA(IF(武备!B38=0,"",VLOOKUP(武备!B38,武器与防具与弹药!$AI$6:武器与防具与弹药!$AM$32,3,FALSE)),"") | BK4: =_xlfn.IFNA(IF(武备!B38=0,"",VLOOKUP(武备!B38,武器与防具与弹药!$AI$6:武器与防具与弹药!$AM$32,4,FALSE)),"") | BL4: =_xlfn.IFNA(IF(武备!B38=0,"",VLOOKUP(武备!B38,武器与防具与弹药!$AI$6:武器与防具与弹药!$AM$32,5,FALSE)),"") | BN4: =_xlfn.IFNA(IF(武备!C46=0,"",VLOOKUP(武备!C46,附表!$AC$2:附表!$AF$61,2,FALSE)),"") | BO4: =_xlfn.IFNA(IF(武备!C46=0,"",VLOOKUP(武备!C46,附表!$AC$2:附表!$AF$61,3,FALSE)),"") | BP4: =_xlfn.IFNA(IF(武备!C46=0,"",VLOOKUP(武备!C46,附表!$AC$2:附表!$AF$61,4,FALSE)),"") | BR4: =_xlfn.IFNA(IF(武备!K78=0,"",VLOOKUP(武备!K78,附表!$AJ$53:附表!$AM$64,2,FALSE)),"") | BU4: {=_xlfn.IFNA(IF(武备!B7=0,"",VLOOKUP(武备!B7,人物数据!$V$1:$AC$300,{1,2,3,4,5,6,7,8},FALSE)),"")} | CD4: {=_xlfn.IFNA(IF(武备!B16=0,"",VLOOKUP(武备!B16,人物数据!$AE$1:$AO$300,{1,2,3,4,5,6,7,8,9,10,11},FALSE)),"")}
